Workbook

Sheet 1.1 EU Total Cereals
A1: EU Total Cereals | B1: Weight (t)
A2: Area (1 000 ha) | B2: 50608000
A3: Yield (t/ha) | B3: 5.3
A4: Beginning stocks | B4: 50800000
A5: Gross production | B5: 270200000
A6: Usable production | B6: 267800000
A7: Imports | B7: 33600000
A8: Availability | B8: 352200000
A9: Domestic use | B9: 255600000
A10: - Human | B10: 59500000
A11: - Seed | B11: 9000000
A12: - Industrial | B12: 30300000
A13: o.w. bioethanol/biofuel | B13: 12100000
... A21: Self-sufficiency rate (%) | B21: 105

Sheet 1.2 EU Soft Wheat
A1: EU Soft Wheat | B1: Weight (t)
A2: Area (1 000 ha) | B2: 21916000
A3: Yield (t/ha) | B3: 5.8
A4: Beginning stocks | B4: 19500000
A5: Gross production | B5: 126200000
A6: Usable production | B6: 125200000
A7: Imports | B7: 9600000
A8: Availability | B8: 154300000
A9: Domestic use | B9: 101400000
A10: - Human | B10: 41800000
A11: - Seed | B11: 4600000
A12: - Industrial | B12: 9200000
A13: o.w. bioethanol/biofuel | B13: 3400000
... A21: Self-sufficiency rate (%) | B21: 124

Sheet 1.3 EU Durum Wheat
A1: EU Durum Wheat | B1: Weight (t)
A2: Area (1 000 ha) | B2: 2317000
A3: Yield (t/ha) | B3: 3.2
A4: Beginning stocks | B4: 800000
A5: Gross production | B5: 7500000
A6: Usable production | B6: 7400000
A7: Imports | B7: 2500000
A8: Availability | B8: 10700000
A9: Domestic use | B9: 9000000
A10: - Human | B10: 8200000
A11: - Seed | B11: 400000
A12: - Industrial | B12: 100000
A13: - Animal feed | B13: 300000
... A19: Self-sufficiency rate (%) | B19: 83

Sheet 1.4 EU Barley
A1: EU Barley | B1: Weight (t)
A2: Area (1 000 ha) | B2: 10368000
A3: Yield (t/ha) | B3: 4.6
A4: Beginning stocks | B4: 5700000
A5: Gross production | B5: 47500000
A6: Usable production | B6: 47000000
A7: Imports | B7: 2000000
A8: Availability | B8: 54700000
A9: Domestic use | B9: 40800000
A10: - Human | B10: 400000
A11: - Seed | B11: 2100000
A12: - Industrial | B12: 6800000
A13: o.w. bioethanol/biofuel | B13: 500000
... A21: Self-sufficiency rate (%) | B21: 115

Sheet 1.5 EU Maize
A1: EU Maize | B1: Weight (t)
A2: Area (1 000 ha) | B2: 8299000
A3: Yield (t/ha) | B3: 7.4
A4: Beginning stocks | B4: 20200000
A5: Gross production | B5: 61500000
A6: Usable production | B6: 61200000
A7: Imports | B7: 19000000
A8: Availability | B8: 100400000
A9: Domestic use | B9: 76100000
A10: - Human | B10: 4800000
A11: - Seed | B11: 400000
A12: - Industrial | B12: 12000000
A13: o.w. bioethanol/biofuel | B13: 6900000
... A21: Self-sufficiency rate (%) | B21: 80

Sheet 1.6 EU Rye
A1: EU Rye | B1: Weight (t)
A2: Area (1 000 ha) | B2: 1859000
A3: Yield (t/ha) | B3: 4.1
A4: Beginning stocks | B4: 1000000
A5: Gross production | B5: 7600000
A6: Usable production | B6: 7400000
A7: Imports | B7: 200000
A8: Availability | B8: 8600000
A9: Domestic use | B9: 7500000
A10: - Human | B10: 3100000
A11: - Seed | B11: 300000
A12: - Industrial | B12: 1500000
A13: o.w. bioethanol/biofuel | B13: 900000
... A21: Self-sufficiency rate (%) | B21: 98

Sheet 1.7 EU Sorghum
A1: EU Sorghum | B1: Weight (t)
A2: Area (1 000 ha) | B2: 156000
A3: Yield (t/ha) | B3: 5.3
A4: Beginning stocks | B4: 500000
A5: Gross production | B5: 800000
A6: Usable production | B6: 800000
A7: Imports | B7: 0
A8: Availability | B8: 1300000
A9: Domestic use | B9: 1100000
A10: - Human | B10: 200000
A11: - Seed | B11: 0
A12: - Industrial | B12: 0
A13: - Animal feed | B13: 900000
... A19: Self-sufficiency rate (%) | B19: 71

Sheet 1.8 EU Oats
A1: EU Oats | B1: Weight (t)
A2: Area (1 000 ha) | B2: 2305000
A3: Yield (t/ha) | B3: 2.6
A4: Beginning stocks | B4: 1300000
A5: Gross production | B5: 5900000
A6: Usable production | B6: 5800000
A7: Imports | B7: 100000
A8: Availability | B8: 7300000
A9: Domestic use | B9: 6400000
A10: - Human | B10: 1100000
A11: - Seed | B11: 400000
A12: - Industrial | B12: 100000
A13: - Animal feed | B13: 4800000
... A19: Self-sufficiency rate (%) | B19: 91

Sheet 1.9 EU Triticale
A1: EU Triticale | B1: Weight (t)
A2: Area (1 000 ha) | B2: 2551000
A3: Yield (t/ha) | B3: 4.3
A4: Beginning stocks | B4: 1600000
A5: Gross production | B5: 11000000
A6: Usable production | B6: 10700000
A7: Imports | B7: 0
A8: Availability | B8: 12300000
A9: Domestic use | B9: 11000000
A10: - Human | B10: 100000
A11: - Seed | B11: 500000
A12: - Industrial | B12: 400000
A13: o.w. bioethanol/biofuel | B13: 0
... A20: Self-sufficiency rate (%) | B20: 98

Sheet 1.10 EU Other Cereals
A1: EU Other Cereals | B1: Weight (t)
A2: Area (1 000 ha) | B2: 837000
A3: Yield (t/ha) | B3: 2.8
A4: Beginning stocks | B4: 300000
A5: Gross production | B5: 2300000
A6: Usable production | B6: 2200000
A7: Imports | B7: 100000
A8: Availability | B8: 2700000
A9: Domestic use | B9: 2400000
A10: - Human | B10: 0
A11: - Seed | B11: 300000
A12: - Industrial | B12: 200000
A13: - Animal feed | B13: 2000000
... A19: Self-sufficiency rate (%) | B19: 91

Sheet 1.11 EU Oilseeds
A1: EU Oilseeds | C1: Meal (t) | D1: Meal (incl. Imports) (t) | E1: Oil (t) | F1: Oil (incl. Imports) (t) | G1: Oil for Food | H1: Oil for Industry | I1: Remaining
A2: Area (1 000 ha) | B2: 11866000
A3: Rapeseed | B3: 6193000
A4: Soya beans | B4: 985000
A5: Sunflower | B5: 4688000
A6: Yield (t/ha) | B6: 2.7
A7: Rapeseed | B7: 3.2
A8: Soya beans | B8: 2.8
A9: Sunflower | B9: 2.1
A10: Production | B10: 32300000
A11: Rapeseed | B11: 19700000
A12: Soya beans | B12: 2800000
A13: Sunflower | B13: 9800000
A14: Domestic use | B14: 50100000
A15: Rapeseed | B15: 24300000 | I15: =B15-B16-('[1]2023-24'!$F$24*1000000) -> 401832.1
A16: of which crushing | B16: 23700000 | C16: ='1.12 EU Oilmeals'!B7-'1.12 EU Oilmeals'!B11 -> 12600000 | D16: ='1.12 EU Oilmeals'!B7 -> 13400000 | E16: ='1.13 EU Vegetable Oils'!B8-'1.13 EU Vegetable Oils'!B13 -> 8900000 | F16: ='1.13 EU Vegetable Oils'!B8 -> 9400000 | G16: =F16*C62 -> 2460733 | H16: =F16*C61 -> 6890052.4 | I16: =B16-C16-E16 -> 2200000
A17: Soya beans | B17: 15700000 | D17: =D16/(D16+F16+I16) -> 0.536 | I17: =B17-B18-('[1]2023-24'!$F$23*1000000) -> 900000
A18: of which crushing | B18: 13600000 | C18: ='1.12 EU Oilmeals'!B8-'1.12 EU Oilmeals'!B12 -> 10200000 | D18: ='1.12 EU Oilmeals'!B8 -> 25900000 | E18: ='1.13 EU Vegetable Oils'!B9-'1.13 EU Vegetable Oils'!B19 -> 2000000 | F18: ='1.13 EU Vegetable Oils'!B9 -> 2700000 | G18: =F18*C46 -> 1412133.9 | H18: =F18*C45 -> 1225732.2 | I18: =B18-C18-E18 -> 1400000
A19: Sunflower | B19: 10100000 | D19: =D18/(D18+F18+I18) -> 0.86333333 | I19: =B19-B20-('[1]2023-24'!$F$25*1000000) -> 996309.2
A20: of which crushing | B20: 8900000 | C20: ='1.12 EU Oilmeals'!B9-'1.12 EU Oilmeals'!B13 -> 4000000 | D20: ='1.12 EU Oilmeals'!B9 -> 7200000 | E20: ='1.13 EU Vegetable Oils'!B10-'1.13 EU Vegetable Oils'!B15 -> 2600000 | F20: ='1.13 EU Vegetable Oils'!B10 -> 5600000 | G20: =F20*C78 -> 5083588 | H20: =F20*C77 -> 503325.54 | I20: =B20-C20-E20 -> 2300000
A21: Imports | B21: 19500000 | D21: =D20/(D20+F20+I20) -> 0.47682119
A22: Rapeseed | B22: 5500000
A23: Soya beans | B23: 13200000
A24: Sunflower | B24: 800000
A25: Exports | B25: 1200000
A26: Rapeseed | B26: 500000
A27: Soya beans | B27: 200000
A28: Sunflower | B28: 500000
A29: Ending stocks | B29: 3000000
A30: Rapeseed | B30: 800000
A31: Soya beans | B31: 1300000
A32: Sunflower | B32: 900000
A33: Self-sufficiency rate (%) | B33: 65
A35: https://apps.fas.usda.gov/newgainapi/api/Report/DownloadReportByFileName?fileName=Oilseeds+and+Products+Annual_Vienna_European+Union_E42023-0015.pdf
A36: Soybean
A37: Item | B37: 2023/24 (t) | C37: Share of Total Dom. Cons. (decimal)
A38: Crush | B38: 15500000
A39: Extraction Rate | B39: 0.19
A40: Beginning Stocks | B40: 369000
A41: Production | B41: 2945000
...

Sheet 1.12 EU Oilmeals
A1: EU Oilmeals | B1: Weight (t) | C1: Primary Crop Equivalent | D1: Meal remaining after animal feed
A2: Production | B2: 29100000 | C2: =SUM(C3:C5) -> 49841485
A3: Rapeseed | B3: 13500000 | C3: =B3/[2]Assumptions_Conversions!$D$3 -> 23275862
A4: Soya beans | B4: 10800000 | C4: =B4/[2]Assumptions_Conversions!$D$5 -> 13670886
A5: Sunflower | B5: 4900000 | C5: =B5/[2]Assumptions_Conversions!$D$4 -> 12894737
A6: Domestic use | B6: 46500000 | C6: =SUM(C7:C9) -> 74835627
A7: Rapeseed | B7: 13400000 | C7: =B7/[2]Assumptions_Conversions!$D$3 -> 23103448 | D7: =B7-('[1]2023-24'!$F$45*1000000) -> -533155.67
A8: Soya beans | B8: 25900000 | C8: =B8/[2]Assumptions_Conversions!$D$5 -> 32784810 | D8: =B8-('[1]2023-24'!$F$38*1000000) -> 115776.08
A9: Sunflower | B9: 7200000 | C9: =B9/[2]Assumptions_Conversions!$D$4 -> 18947368 | D9: =B9-('[1]2023-24'!$F$51*1000000) -> 290479.54
A10: Imports | B10: 19800000 | C10: =SUM(C11:C13) -> 29673781
A11: Rapeseed | B11: 800000 | C11: =B11/[2]Assumptions_Conversions!$D$3 -> 1379310.3
A12: Soya beans | B12: 15700000 | C12: =B12/[2]Assumptions_Conversions!$D$5 -> 19873418
A13: Sunflower | B13: 3200000 | C13: =B13/[2]Assumptions_Conversions!$D$4 -> 8421052.6
A14: Exports | B14: 2400000 | C14: =SUM(C15:C17) -> 4942796.8
A15: Rapeseed | B15: 900000 | C15: =B15/[2]Assumptions_Conversions!$D$3 -> 1551724.1
A16: Soya beans | B16: 600000 | C16: =B16/[2]Assumptions_Conversions!$D$5 -> 759493.67
A17: Sunflower | B17: 1000000 | C17: =B17/[2]Assumptions_Conversions!$D$4 -> 2631578.9
A18: Ending stocks | B18: 500000
A19: Rapeseed | B19: 100000
A20: Soya beans | B20: 300000
A21: Sunflower | B21: 100000
A22: Self-sufficiency rate (%) | B22: 63

Sheet 1.13 EU Vegetable Oils
A1: EU Vegetable Oils | B1: Weight (t)
A2: Production | B2: 16200000
A3: Rapeseed | B3: 9700000
A4: Soya beans | B4: 2700000
A5: Sunflower | B5: 3700000
A6: Palm | B6: 0
A7: Domestic use | B7: 21700000
A8: Rapeseed | B8: 9400000
A9: Soya beans | B9: 2700000
A10: Sunflower | B10: 5600000
A11: Palm | B11: 3900000
A12: Imports | B12: 8100000
A13: Rapeseed | B13: 500000
... A21: Palm | B21: 100000
A22: Ending stocks | B22: 1.5 1.5 1.5
A23: Rapeseed | B23: 600000
A24: Soya beans | B24: 200000
A25: Sunflower | B25: 300000
A26: Palm | B26: 500000
A27: Self-sufficiency rate (%) | B27: 758284

Sheet 1.14 EU Protein Crops
A1: EU Protein Crops | B1: Weight (t)
A2: Area (1 000 ha) | B2: 2503000
A3: Field peas | B3: 982000000
A4: Broad beans | B4: 478000000
A5: Lupins | B5: 222000000
A6: other dry pulses | B6: 820000000
A7: Yield (t/ha) | B7: 1.6
A8: Field peas | B8: 1940000
A9: Broad beans | B9: 2440000
A10: Lupins | B10: 1640000
A11: other dry pulses | B11: 140000
A12: Production | B12: 4549000000
A13: Field peas | B13: 1907000000
... A40: Self-sufficiency rate (%) | B40: 798381

Sheet 1.15 EU White Sugar
A1: EU White Sugar | B1: Weight (t)
A2: Area (of sugar beet) (1 000 ha) | B2: 1468000
A3: Yield (of sugar beet) (t/ha) | B3: 75.1
A4: Production (of sugar beet) (million t of beet) | B4: 110000000
A5: Beginning stocks | B5: 2100000
A6: White sugar production | B6: 15600000
A7: Imports | B7: 1400000
A8: Availability | B8: 19000000
A9: Domestic use white sugar | B9: 15300000
A10: - Human | B10: 14100000
A11: o.w. net exports in processed products | B11: 1700000
A12: - Industrial | B12: 1200000
A13: o.w. bioethanol | B13: 800000
... A18: Self-sufficiency rate (%) | B18: 102

Sheet 1.16 EU Isoglucose
A1: EU Isoglucose | B1: Weight (t)
A2: Beginning stocks | B2: 19000
A3: Production | B3: 494900
A4: Imports | B4: 2900
A5: Availability | B5: 516800
A6: Domestic use | B6: 446700
A7: Share in caloric sweetener use % | B7: 2.8
A8: Exports | B8: 46100
A9: Total use | B9: 492800
A10: Ending stocks | B10: 24000
A11: Self-sufficiency rate (%) | B11: 111

Sheet 2.1 EU Olive Oil
A1: EU Olive Oil | B1: Weight (t)
A2: Area (of olives for oil) (1 000 ha) | B2: 4677000
A3: Yield (of olives for oil) (t/ha) | B3: 2
A4: Yield (of oil of olives) (oil/kg of olives) | B4: 170
A5: Beginning stocks | B5: 410000
A6: Production | B6: 1532000
A7: Imports | B7: 205000
A8: Exports | B8: 608000
A9: Availability | B9: 1538000
A10: Consumption | B10: 1242000
A11: ES+IT+EL+PT | B11: 941000
A12: rest EU | B12: 300000
A13: Per capita consumption (kg) | B13: 2.8
... A16: Self-sufficiency rate (%) | B16: 123

Sheet 2.2 EU Wine
A1: EU Wine | B1: Weight (t)
A2: Area (million ha) | B2: 3.2
A3: Yield (hl/ha) | B3: 45.3
A4: Vinified production | B4: 143
A5: of which 5 main producing MS1 | B5: 130
A6: of which other EU MS | B6: 14
A7: Domestic use | B7: 134
A8: Human consumption | B8: 96
A9: Per capita consumption (l) | B9: 21.3
A10: other use | B10: 38
A11: Imports | B11: 6
A12: Exports | B12: 29
A13: Ending stocks | B13: 162
A14: Self-sufficiency rate (%) | B14: 107

Sheet 2.3 EU Apples
A1: EU Apples | B1: Weight (t)
A2: Area (1000 ha) | B2: 472000
A3: Yield (t/ha) | B3: 26
A4: Total production | B4: 12053000
A5: of which losses and feed use | B5: 718000
A6: of which usable production | B6: 11335000
A7: Production (fresh) | B7: 6814000
A8: Exports (fresh) | B8: 949000
A9: Imports (fresh) | B9: 249000
A10: Consumption (fresh) | B10: 6000000
A11: Per capita consumption (kg) - fresh | B11: 13.3
A12: Ending stocks1 | B12: 423000
A13: Change in stocks | B13: 113000
... A20: Self-sufficiency rate (processed) % | B20: 100

Sheet 2.4 EU Oranges
A1: EU Oranges | B1: Weight (t)
A2: Area (1000 ha) | B2: 277000
A3: Yield (t/ha) | B3: 21
A4: Total production | B4: 5721000
A5: Production (fresh) | B5: 5022000
A6: Exports (fresh) | B6: 308000
A7: Imports (fresh) | B7: 942000
A8: Consumption (fresh) | B8: 5656000
A9: Per capita consumption (kg) - fresh | B9: 12.5
A10: Self-sufficiency rate (fresh) % | B10: 89
A11: Production (processed) | B11: 699000
A12: Exports (processed) | B12: 1071000
A13: Imports (processed) | B13: 2624000
... A16: Self-sufficiency rate (processed) % | B16: 31

Sheet 2.5 EU Peaches And Nectarines
A1: EU Peaches And Nectarines | B1: Weight (t)
A2: Total area (1000 ha) | B2: 207000
A3: Total Yield (t/ha) | B3: 20
A4: Total production | B4: 4049000
A5: Area (1000 ha) - fresh Yield (t/ha) - fresh | B5: 178000
B6: 19000
A7: Production (fresh) | B7: 3330000
A8: of which IT, EL, ES and FR | B8: 3205000
A9: Exports (fresh) | B9: 259000
A10: Imports (fresh) | B10: 24000
A11: Consumption (fresh) | B11: 3095000
A12: Per capita consumption (kg) - fresh | B12: 6.9
A13: Self-sufficiency rate (fresh) % | B13: 108
A14: Area (1000 ha) - processed | B14: 29000
A15: Yield (t/ha) - processed | B15: 25
A16: Production (processed) | B16: 718000
A17: of which EL and ES | B17: 695000
A18: Exports (processed) | B18: 184000
... A22: Self-sufficiency rate (processed) % | B22: 132

Sheet 2.6 EU Tomatoes
A1: EU Tomatoes | B1: Weight (t)
A2: Total production | B2: 17277000
A3: Production (fresh) | B3: 6934000
A4: Exports (fresh) | B4: 461000
A5: Imports (fresh) | B5: 583000
A6: Consumption (fresh) | B6: 7056000
A7: Per capita consumption (kg) - fresh | B7: 15.8
A8: Self-sufficiency rate (fresh) % | B8: 98
A9: Production (processed) | B9: 10343000
A10: of which ES,IT, PT | B10: 9411000
A11: of which other EU countries | B11: 932000
A12: Exports (processed) | B12: 4618000
A13: Imports (processed) | B13: 1930000
... A16: Self-sufficiency rate (processed) % | B16: 135

Sheet 3.1 EU Milk Supply And Utilisat
A1: EU Milk Supply And Utilisation | B1: Weight (t)
A2: Dairy cows (million heads)1 | B2: 20.5
A3: Milk yield (kg/dairy cow)2 | B3: 7304
A4: Cow milk production (million t) | B4: 152.2
A5: Feed use (million t) | B5: 3.3
A6: On farm use and direct sales (million t) | B6: 6.2
A7: Delivered to dairies (million t) | B7: 142.6
A8: Delivery ratio (%)3 | B8: 93.7
A9: Fat content of milk (%) | B9: 4.1
A10: Protein content of milk (%) | B10: 3.5

Sheet 3.2 EU Cheese
A1: EU Cheese | B1: Weight (t)
A2: Production (in dairies) | B2: 10045000
A3: of which from pure cow's milk | B3: 9164000
A4: of which from other milk1 | B4: 881000
A5: Processed cheese impact2 | B5: 394000
A6: Total production | B6: 10439000
A7: Imports3 | B7: 212000
A8: Exports | B8: 1348000
A9: Domestic use4 | B9: 9303000
A10: Change in stocks | B10: 0
A11: Processing use | B11: 331000
A12: Human consumption | B12: 8972000
A13: per capita consumption (kg) | B13: 20.1
A14: Self-sufficiency rate (%) | B14: 112

Sheet 3.3 EU Fresh Dairy Products
A1: EU Fresh Dairy Products | B1: Weight (t)
A2: Production | B2: 37802000
A3: of which Drinking Milk | B3: 23359000
A4: of which Cream | B4: 2468000
A5: of which Acidified Milk | B5: 7663000
A6: of which other Fresh Products1 | B6: 4311000
A7: Imports | B7: 825000
A8: Exports | B8: 1649000
A9: Consumption2 | B9: 36978000
A10: per capita consumption (kg) | B10: 82.8
A11: Self-sufficiency rate (%) | B11: 102

Sheet 3.4 EU Whole Milk Powder
A1: EU Whole Milk Powder | B1: Weight (t)
A2: Production | B2: 710000
A3: Imports | B3: 42000
A4: Exports | B4: 315000
A5: Domestic use1 | B5: 437000
A6: Self-sufficiency rate (%) | B6: 163

Sheet 3.5 EU Skimmed Milk Powder
A1: EU Skimmed Milk Powder | B1: Weight (t)
A2: Production | B2: 1473000
A3: Imports | B3: 56000
A4: Exports | B4: 945000
A5: Domestic use1 | B5: 805000
A6: Ending stocks | B6: 90000
A7: Private | B7: 90000
A8: Public (intervention) | B8: 0
A9: Change in stocks | B9: -221000
A10: Self-sufficiency rate (%) | B10: 183

Sheet 3.6 EU Butter Market
A1: EU Butter Market | B1: Weight (t)
A2: Production | B2: 2346000
A3: Imports | B3: 48000
A4: Exports | B4: 283000
A5: Domestic use1 | B5: 2096000
A6: per capita consumption (kg) | B6: 4.7
A7: Ending stocks | B7: 135000
A8: Private | B8: 135000
A9: Public (intervention) | B9: 0
A10: Change in stocks | B10: 15000
A11: Self-sufficiency rate (%) | B11: 112

Sheet 3.7 EU Whey Market
A1: EU Whey Market | B1: Weight (t)
A2: Production | B2: 2099000
A3: Imports | B3: 69000
A4: Exports | B4: 638000
A5: Domestic use1 | B5: 1530000
A6: Self-sufficiency rate (%) | B6: 137

Sheet 4.1 EU Aggregate Meat
A1: EU Aggregate Meat | B1: Weight (t)
A2: Gross Indigenous Production | B2: 44352000
A3: Live Imports | B3: 11000
A4: Live Exports | B4: 352000
A5: Net Production | B5: 44011000
A6: Meat Imports | B6: 1560000
A7: Meat Exports | B7: 7309000
A8: Domestic use | B8: 38261000
A9: Per capita consumption1 (kg) | B9: 68.4
A10: Self-sufficiency (%) | B10: 116

Sheet 4.2 EU Beef And Veal
A1: EU Beef And Veal | B1: Weight (t)
A2: Gross Indigenous Production | B2: 7197000
A3: Live Imports | B3: 2000
A4: Live Exports | B4: 236000
A5: Net Production | B5: 6964000
A6: Meat Imports | B6: 387000
A7: Meat Exports | B7: 577000
A8: Domestic use | B8: 6774000
A9: per capita consumption (kg) | B9: 10.6
A10: Self-sufficiency (%) | B10: 106

Sheet 4.3 EU Pigmeat
A1: EU Pigmeat | B1: Weight (t)
A2: Gross Indigenous Production | B2: 23039000
A3: Live Imports | B3: 1000
A4: Live Exports | B4: 43000
A5: Net Production | B5: 22996000
A6: Meat Imports | B6: 162000
A7: Meat Exports | B7: 4177000
A8: Domestic use | B8: 18981000
A9: per capita consumption (kg) | B9: 33.2
A10: Self-sufficiency (%) | B10: 121

Sheet 4.4 EU Poultry Meat
A1: EU Poultry Meat | B1: Weight (t)
A2: Gross Indigenous Production | B2: 13470000
A3: Live Imports | B3: 3000
A4: Live Exports | B4: 10000
A5: Net Production | B5: 13463000
A6: Meat Imports | B6: 849000
A7: Meat Exports | B7: 2499000
A8: Domestic use | B8: 11813000
A9: per capita consumption (kg) | B9: 23.3
A10: Self-sufficiency (%) | B10: 114

Sheet Wheat & Other Cereals
A1: Component | B1: 2023/2024
A2: Area (1 000 ha) | B2: =SUM(C2:I2) -> 31941000 | C2: =IFERROR(VLOOKUP($A2,'1.2 EU Soft Wheat'!$A:$B,2,FALSE),"") -> 21916000 | D2: =IFERROR(VLOOKUP($A2,'1.3 EU Durum Wheat'!$A:$B,2,FALSE),"") -> 2317000 | E2: =IFERROR(VLOOKUP($A2,'1.6 EU Rye'!$A:$B,2,FALSE),"") -> 1859000 | F2: =IFERROR(VLOOKUP($A2,'1.7 EU Sorghum'!$A:$B,2,FALSE),"") -> 156000 | G2: =IFERROR(VLOOKUP($A2,'1.8 EU Oats'!$A:$B,2,FALSE),"") -> 2305000 | H2: =IFERROR(VLOOKUP($A2,'1.9 EU Triticale'!$A:$B,2,FALSE),"") -> 2551000 | I2: =IFERROR(VLOOKUP($A2,'1.10 EU Other Cereals'!$A:$B,2,FALSE),"") -> 837000
A3: Yield (t/ha) | B3: =IFERROR(AVERAGE(C3:I3),"") -> 4.0142857 | C3: =IFERROR(VLOOKUP($A3,'1.2 EU Soft Wheat'!$A:$B,2,FALSE),"") -> 5.8 | D3: =IFERROR(VLOOKUP($A3,'1.3 EU Durum Wheat'!$A:$B,2,FALSE),"") -> 3.2 | E3: =IFERROR(VLOOKUP($A3,'1.6 EU Rye'!$A:$B,2,FALSE),"") -> 4.1 | F3: =IFERROR(VLOOKUP($A3,'1.7 EU Sorghum'!$A:$B,2,FALSE),"") -> 5.3 | G3: =IFERROR(VLOOKUP($A3,'1.8 EU Oats'!$A:$B,2,FALSE),"") -> 2.6 | H3: =IFERROR(VLOOKUP($A3,'1.9 EU Triticale'!$A:$B,2,FALSE),"") -> 4.3 | I3: =IFERROR(VLOOKUP($A3,'1.10 EU Other Cereals'!$A:$B,2,FALSE),"") -> 2.8
A4: Beginning stocks | B4: =SUM(C4:I4) -> 25000000 | C4: =IFERROR(VLOOKUP($A4,'1.2 EU Soft Wheat'!$A:$B,2,FALSE),"") -> 19500000 | D4: =IFERROR(VLOOKUP($A4,'1.3 EU Durum Wheat'!$A:$B,2,FALSE),"") -> 800000 | E4: =IFERROR(VLOOKUP($A4,'1.6 EU Rye'!$A:$B,2,FALSE),"") -> 1000000 | F4: =IFERROR(VLOOKUP($A4,'1.7 EU Sorghum'!$A:$B,2,FALSE),"") -> 500000 | G4: =IFERROR(VLOOKUP($A4,'1.8 EU Oats'!$A:$B,2,FALSE),"") -> 1300000 | H4: =IFERROR(VLOOKUP($A4,'1.9 EU Triticale'!$A:$B,2,FALSE),"") -> 1600000 | I4: =IFERROR(VLOOKUP($A4,'1.10 EU Other Cereals'!$A:$B,2,FALSE),"") -> 300000
A5: Gross production | B5: =SUM(C5:I5) -> 161300000 | C5: =IFERROR(VLOOKUP($A5,'1.2 EU Soft Wheat'!$A:$B,2,FALSE),"") -> 126200000 | D5: =IFERROR(VLOOKUP($A5,'1.3 EU Durum Wheat'!$A:$B,2,FALSE),"") -> 7500000 | E5: =IFERROR(VLOOKUP($A5,'1.6 EU Rye'!$A:$B,2,FALSE),"") -> 7600000 | F5: =IFERROR(VLOOKUP($A5,'1.7 EU Sorghum'!$A:$B,2,FALSE),"") -> 800000 | G5: =IFERROR(VLOOKUP($A5,'1.8 EU Oats'!$A:$B,2,FALSE),"") -> 5900000 | H5: =IFERROR(VLOOKUP($A5,'1.9 EU Triticale'!$A:$B,2,FALSE),"") -> 11000000 | I5: =IFERROR(VLOOKUP($A5,'1.10 EU Other Cereals'!$A:$B,2,FALSE),"") -> 2300000
A6: Usable production | B6: =SUM(C6:I6) -> 159500000 | C6: =IFERROR(VLOOKUP($A6,'1.2 EU Soft Wheat'!$A:$B,2,FALSE),"") -> 125200000 | D6: =IFERROR(VLOOKUP($A6,'1.3 EU Durum Wheat'!$A:$B,2,FALSE),"") -> 7400000 | E6: =IFERROR(VLOOKUP($A6,'1.6 EU Rye'!$A:$B,2,FALSE),"") -> 7400000 | F6: =IFERROR(VLOOKUP($A6,'1.7 EU Sorghum'!$A:$B,2,FALSE),"") -> 800000 | G6: =IFERROR(VLOOKUP($A6,'1.8 EU Oats'!$A:$B,2,FALSE),"") -> 5800000 | H6: =IFERROR(VLOOKUP($A6,'1.9 EU Triticale'!$A:$B,2,FALSE),"") -> 10700000 | I6: =IFERROR(VLOOKUP($A6,'1.10 EU Other Cereals'!$A:$B,2,FALSE),"") -> 2200000
A7: Imports | B7: =SUM(C7:I7) -> 12500000 | C7: =IFERROR(VLOOKUP($A7,'1.2 EU Soft Wheat'!$A:$B,2,FALSE),"") -> 9600000 | D7: =IFERROR(VLOOKUP($A7,'1.3 EU Durum Wheat'!$A:$B,2,FALSE),"") -> 2500000 | E7: =IFERROR(VLOOKUP($A7,'1.6 EU Rye'!$A:$B,2,FALSE),"") -> 200000 | F7: =IFERROR(VLOOKUP($A7,'1.7 EU Sorghum'!$A:$B,2,FALSE),"") -> 0 | G7: =IFERROR(VLOOKUP($A7,'1.8 EU Oats'!$A:$B,2,FALSE),"") -> 100000 | H7: =IFERROR(VLOOKUP($A7,'1.9 EU Triticale'!$A:$B,2,FALSE),"") -> 0 | I7: =IFERROR(VLOOKUP($A7,'1.10 EU Other Cereals'!$A:$B,2,FALSE),"") -> 100000
A8: Availability | B8: =SUM(C8:I8) -> 197200000 | C8: =IFERROR(VLOOKUP($A8,'1.2 EU Soft Wheat'!$A:$B,2,FALSE),"") -> 154300000 | D8: =IFERROR(VLOOKUP($A8,'1.3 EU Durum Wheat'!$A:$B,2,FALSE),"") -> 10700000 | E8: =IFERROR(VLOOKUP($A8,'1.6 EU Rye'!$A:$B,2,FALSE),"") -> 8600000 | F8: =IFERROR(VLOOKUP($A8,'1.7 EU Sorghum'!$A:$B,2,FALSE),"") -> 1300000 | G8: =IFERROR(VLOOKUP($A8,'1.8 EU Oats'!$A:$B,2,FALSE),"") -> 7300000 | H8: =IFERROR(VLOOKUP($A8,'1.9 EU Triticale'!$A:$B,2,FALSE),"") -> 12300000 | I8: =IFERROR(VLOOKUP($A8,'1.10 EU Other Cereals'!$A:$B,2,FALSE),"") -> 2700000
A9: Domestic use | B9: =SUM(C9:I9) -> 138800000 | C9: =IFERROR(VLOOKUP($A9,'1.2 EU Soft Wheat'!$A:$B,2,FALSE),"") -> 101400000 | D9: =IFERROR(VLOOKUP($A9,'1.3 EU Durum Wheat'!$A:$B,2,FALSE),"") -> 9000000 | E9: =IFERROR(VLOOKUP($A9,'1.6 EU Rye'!$A:$B,2,FALSE),"") -> 7500000 | F9: =IFERROR(VLOOKUP($A9,'1.7 EU Sorghum'!$A:$B,2,FALSE),"") -> 1100000 | G9: =IFERROR(VLOOKUP($A9,'1.8 EU Oats'!$A:$B,2,FALSE),"") -> 6400000 | H9: =IFERROR(VLOOKUP($A9,'1.9 EU Triticale'!$A:$B,2,FALSE),"") -> 11000000 | I9: =IFERROR(VLOOKUP($A9,'1.10 EU Other Cereals'!$A:$B,2,FALSE),"") -> 2400000
A10: - Human | B10: =SUM(C10:I10) -> 54500000 | C10: =IFERROR(VLOOKUP($A10,'1.2 EU Soft Wheat'!$A:$B,2,FALSE),"") -> 41800000 | D10: =IFERROR(VLOOKUP($A10,'1.3 EU Durum Wheat'!$A:$B,2,FALSE),"") -> 8200000 | E10: =IFERROR(VLOOKUP($A10,'1.6 EU Rye'!$A:$B,2,FALSE),"") -> 3100000 | F10: =IFERROR(VLOOKUP($A10,'1.7 EU Sorghum'!$A:$B,2,FALSE),"") -> 200000 | G10: =IFERROR(VLOOKUP($A10,'1.8 EU Oats'!$A:$B,2,FALSE),"") -> 1100000 | H10: =IFERROR(VLOOKUP($A10,'1.9 EU Triticale'!$A:$B,2,FALSE),"") -> 100000 | I10: =IFERROR(VLOOKUP($A10,'1.10 EU Other Cereals'!$A:$B,2,FALSE),"") -> 0
A11: - Seed | B11: =SUM(C11:I11) -> 6500000 | C11: =IFERROR(VLOOKUP($A11,'1.2 EU Soft Wheat'!$A:$B,2,FALSE),"") -> 4600000 | D11: =IFERROR(VLOOKUP($A11,'1.3 EU Durum Wheat'!$A:$B,2,FALSE),"") -> 400000 | E11: =IFERROR(VLOOKUP($A11,'1.6 EU Rye'!$A:$B,2,FALSE),"") -> 300000 | F11: =IFERROR(VLOOKUP($A11,'1.7 EU Sorghum'!$A:$B,2,FALSE),"") -> 0 | G11: =IFERROR(VLOOKUP($A11,'1.8 EU Oats'!$A:$B,2,FALSE),"") -> 400000 | H11: =IFERROR(VLOOKUP($A11,'1.9 EU Triticale'!$A:$B,2,FALSE),"") -> 500000 | I11: =IFERROR(VLOOKUP($A11,'1.10 EU Other Cereals'!$A:$B,2,FALSE),"") -> 300000
A12: - Industrial | B12: =SUM(C12:I12) -> 11500000 | C12: =IFERROR(VLOOKUP($A12,'1.2 EU Soft Wheat'!$A:$B,2,FALSE),"") -> 9200000 | D12: =IFERROR(VLOOKUP($A12,'1.3 EU Durum Wheat'!$A:$B,2,FALSE),"") -> 100000 | E12: =IFERROR(VLOOKUP($A12,'1.6 EU Rye'!$A:$B,2,FALSE),"") -> 1500000 | F12: =IFERROR(VLOOKUP($A12,'1.7 EU Sorghum'!$A:$B,2,FALSE),"") -> 0 | G12: =IFERROR(VLOOKUP($A12,'1.8 EU Oats'!$A:$B,2,FALSE),"") -> 100000 | H12: =IFERROR(VLOOKUP($A12,'1.9 EU Triticale'!$A:$B,2,FALSE),"") -> 400000 | I12: =IFERROR(VLOOKUP($A12,'1.10 EU Other Cereals'!$A:$B,2,FALSE),"") -> 200000
A13: o.w. bioethanol/biofuel | B13: =SUM(C13:I13) -> 4300000 | C13: =IFERROR(VLOOKUP($A13,'1.2 EU Soft Wheat'!$A:$B,2,FALSE),"") -> 3400000 | D13: =IFERROR(VLOOKUP($A13,'1.3 EU Durum Wheat'!$A:$B,2,FALSE),"") | E13: =IFERROR(VLOOKUP($A13,'1.6 EU Rye'!$A:$B,2,FALSE),"") -> 900000 | F13: =IFERROR(VLOOKUP($A13,'1.7 EU Sorghum'!$A:$B,2,FALSE),"") | G13: =IFERROR(VLOOKUP($A13,'1.8 EU Oats'!$A:$B,2,FALSE),"") | H13: =IFERROR(VLOOKUP($A13,'1.9 EU Triticale'!$A:$B,2,FALSE),"") -> 0 | I13: =IFERROR(VLOOKUP($A13,'1.10 EU Other Cereals'!$A:$B,2,FALSE),"")
A14: - Animal feed | B14: =SUM(C14:I14) -> 66500000 | C14: =IFERROR(VLOOKUP($A14,'1.2 EU Soft Wheat'!$A:$B,2,FALSE),"") -> 45800000 | D14: =IFERROR(VLOOKUP($A14,'1.3 EU Durum Wheat'!$A:$B,2,FALSE),"") -> 300000 | E14: =IFERROR(VLOOKUP($A14,'1.6 EU Rye'!$A:$B,2,FALSE),"") -> 2700000 | F14: =IFERROR(VLOOKUP($A14,'1.7 EU Sorghum'!$A:$B,2,FALSE),"") -> 900000 | G14: =IFERROR(VLOOKUP($A14,'1.8 EU Oats'!$A:$B,2,FALSE),"") -> 4800000 | H14: =IFERROR(VLOOKUP($A14,'1.9 EU Triticale'!$A:$B,2,FALSE),"") -> 10000000 | I14: =IFERROR(VLOOKUP($A14,'1.10 EU Other Cereals'!$A:$B,2,FALSE),"") -> 2000000
A15: Losses (excl. on-farm) | B15: =SUM(C15:I15) -> 900000 | C15: =IFERROR(VLOOKUP($A15,'1.2 EU Soft Wheat'!$A:$B,2,FALSE),"") -> 800000 | D15: =IFERROR(VLOOKUP($A15,'1.3 EU Durum Wheat'!$A:$B,2,FALSE),"") -> 0 | E15: =IFERROR(VLOOKUP($A15,'1.6 EU Rye'!$A:$B,2,FALSE),"") -> 0 | F15: =IFERROR(VLOOKUP($A15,'1.7 EU Sorghum'!$A:$B,2,FALSE),"") -> 0 | G15: =IFERROR(VLOOKUP($A15,'1.8 EU Oats'!$A:$B,2,FALSE),"") -> 0 | H15: =IFERROR(VLOOKUP($A15,'1.9 EU Triticale'!$A:$B,2,FALSE),"") -> 100000 | I15: =IFERROR(VLOOKUP($A15,'1.10 EU Other Cereals'!$A:$B,2,FALSE),"") -> 0
... A20: - Intervention | B20: =SUM(C20:I20) -> 0 | C20: =IFERROR(VLOOKUP($A20,'1.2 EU Soft Wheat'!$A:$B,2,FALSE),"") -> 0 | D20: =IFERROR(VLOOKUP($A20,'1.3 EU Durum Wheat'!$A:$B,2,FALSE),"") | E20: =IFERROR(VLOOKUP($A20,'1.6 EU Rye'!$A:$B,2,FALSE),"") -> 0 | F20: =IFERROR(VLOOKUP($A20,'1.7 EU Sorghum'!$A:$B,2,FALSE),"") | G20: =IFERROR(VLOOKUP($A20,'1.8 EU Oats'!$A:$B,2,FALSE),"") | H20: =IFERROR(VLOOKUP($A20,'1.9 EU Triticale'!$A:$B,2,FALSE),"") | I20: =IFERROR(VLOOKUP($A20,'1.10 EU Other Cereals'!$A:$B,2,FALSE),"")
A21: Self-sufficiency rate (%) | B21: =IFERROR(AVERAGE(C21:I21),"") -> 93.714286 | C21: =IFERROR(VLOOKUP($A21,'1.2 EU Soft Wheat'!$A:$B,2,FALSE),"") -> 124 | D21: =IFERROR(VLOOKUP($A21,'1.3 EU Durum Wheat'!$A:$B,2,FALSE),"") -> 83 | E21: =IFERROR(VLOOKUP($A21,'1.6 EU Rye'!$A:$B,2,FALSE),"") -> 98 | F21: =IFERROR(VLOOKUP($A21,'1.7 EU Sorghum'!$A:$B,2,FALSE),"") -> 71 | G21: =IFERROR(VLOOKUP($A21,'1.8 EU Oats'!$A:$B,2,FALSE),"") -> 91 | H21: =IFERROR(VLOOKUP($A21,'1.9 EU Triticale'!$A:$B,2,FALSE),"") -> 98 | I21: =IFERROR(VLOOKUP($A21,'1.10 EU Other Cereals'!$A:$B,2,FALSE),"") -> 91
