Workbook

Sheet Summary
A6: Crop production in EU standard humidity [apro_cpsh1__custom_18188015]
A7: Open product page | B7: Open in Data Browser
A8: Description: | B8: -
A10: Last update of data: | D10: 17/09/2025 23:00
A11: Last change of data structure: | D11: 26/08/2025 23:00
B13: Institutional source(s)
C14: Eurostat
B15: Contents | C15: Time frequency | D15: Crops | E15: Structure of production
B16: Sheet 1 | C16: Annual | D16: Cereals for the production of grain (including seed) | E16: Area (cultivation/harvested/production) (1000 ha)
B17: Flags 1 | C17: Annual | D17: Cereals for the production of grain (including seed) | E17: Area (cultivation/harvested/production) (1000 ha)
B18: Sheet 2 | C18: Annual | D18: Cereals for the production of grain (including seed) | E18: Harvested production in EU standard humidity (1000 t)
B19: Flags 2 | C19: Annual | D19: Cereals for the production of grain (including seed) | E19: Harvested production in EU standard humidity (1000 t)
B20: Sheet 3 | C20: Annual | D20: Cereals for the production of grain (including seed) | E20: Yield in EU standard humidity (tonne/ha)
B21: Flags 3 | C21: Annual | D21: Cereals for the production of grain (including seed) | E21: Yield in EU standard humidity (tonne/ha)
B22: Sheet 4 | C22: Annual | D22: Cereals (excluding rice) for the production of grain (including seed) | E22: Area (cultivation/harvested/production) (1000 ha)
B23: Flags 4 | C23: Annual | D23: Cereals (excluding rice) for the production of grain (including seed) | E23: Area (cultivation/harvested/production) (1000 ha)
B24: Sheet 5 | C24: Annual | D24: Cereals (excluding rice) for the production of grain (including seed) | E24: Harvested production in EU standard humidity (1000 t)
B25: Flags 5 | C25: Annual | D25: Cereals (excluding rice) for the production of grain (including seed) | E25: Harvested production in EU standard humidity (1000 t)
B26: Sheet 6 | C26: Annual | D26: Cereals (excluding rice) for the production of grain (including seed) | E26: Yield in EU standard humidity (tonne/ha)
... B207: Flags 18 | C207: Annual | D207: Cultivated mushrooms | E207: Yield in EU standard humidity (tonne/ha)

Sheet Structure
A1: Structure
B2: Dimension | C2: Position
B3: Label | C3: Label
B4: Time frequency | C4: Annual
B5: Crops | C5: Cereals for the production of grain (including seed)
B6: Crops | C6: Cereals (excluding rice) for the production of grain (including seed)
B7: Crops | C7: Wheat and spelt
B8: Crops | C8: Common wheat and spelt
B9: Crops | C9: Rye
B10: Crops | C10: Barley
B11: Crops | C11: Oats
B12: Crops | C12: Grain maize and corn-cob-mix
B13: Crops | C13: Triticale
... B84: Time | C84: 2025

Sheet EU27_2023_Summary
A1: Crop Category | B1: Area (1000 ha) | C1: Production (1000 t) | D1: Yield (t/ha)
A3: Cereals for the production of grain (including seed) | B3: =(IF('Sheet 1'!I12 = ":", SUM('Sheet 1'!I14:I40), 'Sheet 1'!I12))*1000 -> 50965830 | C3: =(IF('Sheet 2'!I12 = ":", SUM('Sheet 2'!I14:I40), 'Sheet 2'!I12))*1000 -> 271644810 | D3: =IF('Sheet 3'!I12 = ":", C3/B3, 'Sheet 3'!I12) -> 5.3299399
A4: Cereals (excluding rice) for the production of grain (including seed) | B4: =(IF('Sheet 4'!I12 = ":", SUM('Sheet 4'!I14:I40), 'Sheet 4'!I12))*1000 -> 50616790 | C4: =(IF('Sheet 5'!I12 = ":", SUM('Sheet 5'!I14:I40), 'Sheet 5'!I12))*1000 -> 269370580 | D4: =IF('Sheet 6'!I12 = ":", C4/B4, 'Sheet 6'!I12) -> 5.3217634
A5: Wheat and spelt | B5: =(IF('Sheet 7'!I12 = ":", SUM('Sheet 7'!I14:I40), 'Sheet 7'!I12))*1000 -> 24232800 | C5: =(IF('Sheet 8'!I12 = ":", SUM('Sheet 8'!I14:I40), 'Sheet 8'!I12))*1000 -> 1.3348117e+08 | D5: =IF('Sheet 9'!I12 = ":", C5/B5, 'Sheet 9'!I12) -> 5.5082851
A6: Common wheat and spelt | B6: =(IF('Sheet 10'!I12 = ":", SUM('Sheet 10'!I14:I40), 'Sheet 10'!I12))*1000 -> 21915630 | C6: =(IF('Sheet 11'!I12 = ":", SUM('Sheet 11'!I14:I40), 'Sheet 11'!I12))*1000 -> 125878520 | D6: =IF('Sheet 12'!I12 = ":", C6/B6, 'Sheet 12'!I12) -> 5.7437783
A7: Rye | B7: =(IF('Sheet 13'!I12 = ":", SUM('Sheet 13'!I14:I40), 'Sheet 13'!I12))*1000 -> 1856350 | C7: =(IF('Sheet 14'!I12 = ":", SUM('Sheet 14'!I14:I40), 'Sheet 14'!I12))*1000 -> 7492690 | D7: =IF('Sheet 15'!I12 = ":", C7/B7, 'Sheet 15'!I12) -> 4.0362486
A8: Barley | B8: =(IF('Sheet 16'!I12 = ":", SUM('Sheet 16'!I14:I40), 'Sheet 16'!I12))*1000 -> 10368150 | C8: =(IF('Sheet 17'!I12 = ":", SUM('Sheet 17'!I14:I40), 'Sheet 17'!I12))*1000 -> 47389510 | D8: =IF('Sheet 18'!I12 = ":", C8/B8, 'Sheet 18'!I12) -> 4.5706814
A9: Oats | B9: =(IF('Sheet 19'!I12 = ":", SUM('Sheet 19'!I14:I40), 'Sheet 19'!I12))*1000 -> 2305110 | C9: =(IF('Sheet 20'!I12 = ":", SUM('Sheet 20'!I14:I40), 'Sheet 20'!I12))*1000 -> 5888110 | D9: =IF('Sheet 21'!I12 = ":", C9/B9, 'Sheet 21'!I12) -> 2.5543727
A10: Grain maize and corn-cob-mix | B10: =(IF('Sheet 22'!I12 = ":", SUM('Sheet 22'!I14:I40), 'Sheet 22'!I12))*1000 -> 8298970 | C10: =(IF('Sheet 23'!I12 = ":", SUM('Sheet 23'!I14:I40), 'Sheet 23'!I12))*1000 -> 61035300 | D10: =IF('Sheet 24'!I12 = ":", C10/B10, 'Sheet 24'!I12) -> 7.3545633
A11: Triticale | B11: =(IF('Sheet 25'!I12 = ":", SUM('Sheet 25'!I14:I40), 'Sheet 25'!I12))*1000 -> 2550710 | C11: =(IF('Sheet 26'!I12 = ":", SUM('Sheet 26'!I14:I40), 'Sheet 26'!I12))*1000 -> 10872970 | D11: =IF('Sheet 27'!I12 = ":", C11/B11, 'Sheet 27'!I12) -> 4.2627229
A12: Other cereals n.e.c. (buckwheat, millet, canary seed, etc.) | B12: =(IF('Sheet 28'!I12 = ":", SUM('Sheet 28'!I14:I40), 'Sheet 28'!I12))*1000 -> 354570 | C12: =(IF('Sheet 29'!I12 = ":", SUM('Sheet 29'!I14:I40), 'Sheet 29'!I12))*1000 -> 720340 | D12: =IF('Sheet 30'!I12 = ":", C12/B12, 'Sheet 30'!I12) -> 2.0315876
A13: Rice | B13: =(IF('Sheet 31'!I12 = ":", SUM('Sheet 31'!I14:I40), 'Sheet 31'!I12))*1000 -> 348990 | C13: =(IF('Sheet 32'!I12 = ":", SUM('Sheet 32'!I14:I40), 'Sheet 32'!I12))*1000 -> 2234830 | D13: =IF('Sheet 33'!I12 = ":", C13/B13, 'Sheet 33'!I12) -> 6.4037078
A14: Potatoes (including seed potatoes) | B14: =(IF('Sheet 34'!I12 = ":", SUM('Sheet 34'!I14:I40), 'Sheet 34'!I12))*1000 -> 1328950 | C14: =(IF('Sheet 35'!I12 = ":", SUM('Sheet 35'!I14:I40), 'Sheet 35'!I12))*1000 -> 48142050 | D14: =IF('Sheet 36'!I12 = ":", C14/B14, 'Sheet 36'!I12) -> 36.225629
A15: Sugar beet (excluding seed) | B15: =(IF('Sheet 37'!I12 = ":", SUM('Sheet 37'!I14:I40), 'Sheet 37'!I12))*1000 -> 1468070 | C15: =(IF('Sheet 38'!I12 = ":", SUM('Sheet 38'!I14:I40), 'Sheet 38'!I12))*1000 -> 110253300 | D15: =IF('Sheet 39'!I12 = ":", C15/B15, 'Sheet 39'!I12) -> 75.100847
A16: Oilseeds | B16: =(IF('Sheet 40'!I12 = ":", SUM('Sheet 40'!I14:I40), 'Sheet 40'!I12))*1000 -> 12147950 | C16: =(IF('Sheet 41'!I12 = ":", SUM('Sheet 41'!I14:I40), 'Sheet 41'!I12))*1000 -> 33186960 | D16: =IF('Sheet 42'!I12 = ":", C16/B16, 'Sheet 42'!I12) -> 2.731898
A17: Rape, turnip rape, sunflower seeds and soya | B17: =(IF('Sheet 43'!I12 = ":", SUM('Sheet 43'!I14:I40), 'Sheet 43'!I12))*1000 -> 11865590 | C17: =(IF('Sheet 44'!I12 = ":", SUM('Sheet 44'!I14:I40), 'Sheet 44'!I12))*1000 -> 30712750 | D17: =IF('Sheet 45'!I12 = ":", C17/B17, 'Sheet 45'!I12) -> 2.5883879
A18: Rape and turnip rape seeds | B18: =(IF('Sheet 46'!I12 = ":", SUM('Sheet 46'!I14:I40), 'Sheet 46'!I12))*1000 -> 6192830 | C18: =(IF('Sheet 47'!I12 = ":", SUM('Sheet 47'!I14:I40), 'Sheet 47'!I12))*1000 -> 19585220 | D18: =IF('Sheet 48'!I12 = ":", C18/B18, 'Sheet 48'!I12) -> 3.1625638
A19: Sunflower seed | B19: =(IF('Sheet 49'!I12 = ":", SUM('Sheet 49'!I14:I40), 'Sheet 49'!I12))*1000 -> 4687590 | C19: =(IF('Sheet 50'!I12 = ":", SUM('Sheet 50'!I14:I40), 'Sheet 50'!I12))*1000 -> 9829250 | D19: =IF('Sheet 51'!I12 = ":", C19/B19, 'Sheet 51'!I12) -> 2.0968664
A20: Soya | B20: =(IF('Sheet 52'!I12 = ":", SUM('Sheet 52'!I14:I40), 'Sheet 52'!I12))*1000 -> 985130 | C20: =(IF('Sheet 53'!I12 = ":", SUM('Sheet 53'!I14:I40), 'Sheet 53'!I12))*1000 -> 2862230 | D20: =IF('Sheet 54'!I12 = ":", C20/B20, 'Sheet 54'!I12) -> 2.9054338
A21: Linseed (oil flax) | B21: =(IF('Sheet 55'!I12 = ":", SUM('Sheet 55'!I14:I40), 'Sheet 55'!I12))*1000 -> 49450 | C21: =(IF('Sheet 56'!I12 = ":", SUM('Sheet 56'!I14:I40), 'Sheet 56'!I12))*1000 -> 84360 | D21: =IF('Sheet 57'!I12 = ":", C21/B21, 'Sheet 57'!I12) -> 1.7059656
A22: Temporary grasses and grazings | B22: =(IF('Sheet 61'!I12 = ":", SUM('Sheet 61'!I14:I40), 'Sheet 61'!I12))*1000 -> 7198620 | C22: =(IF('Sheet 62'!I12 = ":", SUM('Sheet 62'!I14:I40), 'Sheet 62'!I12))*1000 -> 1.161565e+08 | D22: =IF('Sheet 63'!I12 = ":", C22/B22, 'Sheet 63'!I12) -> 16.13594
A23: Leguminous plants harvested green | B23: =(IF('Sheet 64'!I12 = ":", SUM('Sheet 64'!I14:I40), 'Sheet 64'!I12))*1000 -> 4503120 | C23: =(IF('Sheet 65'!I12 = ":", SUM('Sheet 65'!I14:I40), 'Sheet 65'!I12))*1000 -> 77464040 | D23: =IF('Sheet 66'!I12 = ":", C23/B23, 'Sheet 66'!I12) -> 17.202304
A24: Other leguminous plants harvested green n.e.c. (clover etc.) | B24: =(IF('Sheet 67'!I12 = ":", SUM('Sheet 67'!I14:I40), 'Sheet 67'!I12))*1000 -> 1598890 | C24: =(IF('Sheet 68'!I12 = ":", SUM('Sheet 68'!I14:I40), 'Sheet 68'!I12))*1000 -> 19096070 | D24: =IF('Sheet 69'!I12 = ":", C24/B24, 'Sheet 69'!I12) -> 11.943329
A25: Green maize | B25: =(IF('Sheet 76'!I12 = ":", SUM('Sheet 76'!I14:I40), 'Sheet 76'!I12))*1000 -> 5766630 | C25: =(IF('Sheet 77'!I12 = ":", SUM('Sheet 77'!I14:I40), 'Sheet 77'!I12))*1000 -> 241967510 | D25: =IF('Sheet 78'!I12 = ":", C25/B25, 'Sheet 78'!I12) -> 41.959951

Sheet Sheet 1
A1: Data extracted on 26/09/2025 16:39:19 from [ESTAT]
A2: Dataset: | B2: Crop production in EU standard humidity [apro_cpsh1__custom_18188015]
A3: Last updated: | B3: 17/09/2025 23:00
A5: Time frequency | C5: Annual
A6: Crops | C6: Cereals for the production of grain (including seed)
A7: Structure of production | C7: Area (cultivation/harvested/production) (1000 ha)
A9: TIME | B9: 2016 | C9: 2017 | D9: 2018 | E9: 2019 | F9: 2020 | G9: 2021 | H9: 2022 | I9: 2023 | J9: 2024 | K9: 2025
A10: GEO (Labels)
A11: European Union (EU6-1958, EU9-1973, EU10-1981, EU12-1986, EU15-1995, EU25-2004, EU27-2007, EU28-2013, EU27-2020) | B11: 57220.53 | C11: 55620.91 | D11: 55437.02 | E11: 56870.56 | F11: 52253.08 | G11: 52536.64 | H11: 51474.53 | I11: 50965.83 | J11: 49416.34 | K11: :
A12: European Union - 27 countries (from 2020) | B12: 54092.53 | C12: 52439.91 | D12: 52331.22 | E12: 53659.7 | F12: 52253.08 | G12: 52536.64 | H12: 51474.53 | I12: 50965.83 | J12: 49416.34 | K12: :
A13: European Union - 28 countries (2013-2020) | B13: 57220.53 | C13: 55620.91 | D13: 55437.02 | E13: 56870.56 | F13: : | G13: : | H13: : | I13: : | J13: : | K13: :
A14: Belgium | B14: 337.01 | C14: 305.44 | D14: 304.52 | E14: 313.11 | F14: 304.34 | G14: 310.2 | H14: 323.07 | I14: 324.66 | J14: 281.94 | K14: :
A15: Bulgaria | B15: 1816.64 | C15: 1729.27 | D15: 1817.78 | E15: 1927.57 | F15: 1966.04 | G15: 1956.33 | H15: 1900.65 | I15: 1980.46 | J15: 1968.19 | K15: :
A16: Czechia | B16: 1359.01 | C16: 1354.68 | D16: 1338.78 | E16: 1352.53 | F16: 1344.88 | G16: 1345.84 | H16: 1386.01 | I16: 1317.2 | J16: 1307.64 | K16: :
A17: Denmark | B17: 1464.8 | C17: 1442.7 | D17: 1416.3 | E17: 1373.7 | F17: 1367 | G17: 1359.7 | H17: 1307.1 | I17: 1234.6 | J17: 1229.65 | K17: :
A18: Germany | B18: 6325 | C18: 6276.2 | D18: 6148.9 | E18: 6380 | F18: 6074.9 | G18: 6063.5 | H18: 6112.5 | I18: 6076.2 | J18: 5757.9 | K18: :
A19: Estonia | B19: 351.4 | C19: 330.68 | D19: 350.43 | E19: 364.36 | F19: 370.12 | G19: 367.12 | H19: 361.82 | I19: 352.15 | J19: 349.19 | K19: :
A20: Ireland | B20: 280.34 | C20: 271.68 | D20: 260.97 | E20: 266.66 | F20: 265.63 | G20: 274.66 | H20: 285.66 | I20: 269.36 | J20: 259.18 | K20: :
A21: Greece | B21: 987.95 | C21: 839.17 | D21: 787.98 | E21: 728.14 | F21: 739.88 | G21: 770.9 | H21: 773.27 | I21: 822.26 | J21: 586.08 | K21: :
A22: Spain | B22: 6239.8 | C22: 6015.23 | D22: 6027.61 | E22: 5975.71 | F22: 6069.24 | G22: 6034.58 | H22: 5832.99 | I22: 5444.5 | J22: 5469.78 | K22: :
A23: France | B23: 9529.98 | C23: 9339.87 | D23: 9055.31 | E23: 9394.03 | F23: 8926.69 | G23: 9325.7 | H23: 9005.01 | I23: 8831.54 | J23: 8537.45 | K23: :
A24: Croatia | B24: 528.47 | C24: 461.48 | D24: 459.7 | E24: 490.88 | F24: 535.76 | G24: 519.78 | H24: 519.28 | I24: 539.59 | J24: 495.7 | K24: :
A25: Italy | B25: 3256.99 | C25: 3140.58 | D25: 3092.69 | E25: 3066.52 | F25: 3011.73 | G25: 2978.39 | H25: 3010.64 | I25: 3054.29 | J25: 2837.5 | K25: :
... A41: Iceland | B41: 2 | C41: 2 | D41: 1.5 | E41: 2 | F41: 2.8 | G41: 2.6 | H41: 3.16 | I41: 2.95 | J41: 2.7 | K41: :
A42: Norway | B42: 285.05 | C42: 286.79 | D42: 279.98 | E42: 275.55 | F42: 280.22 | G42: 283.5 | H42: 280.61 | I42: 283.88 | J42: : | K42: :
A43: Switzerland | B43: 144.1 | C43: 143.32 | D43: 141.73 | E43: 141.45 | F43: 144.54 | G43: 141.68 | H43: 141.84 | I43: 141.48 | J43: 136.28 | K43: :
A44: United Kingdom | B44: 3128 | C44: 3181 | D44: 3105.8 | E44: 3210.86 | F44: 3093.38 | G44: : | H44: : | I44: : | J44: : | K44: :
A45: Bosnia and Herzegovina | B45: 313.59 | C45: 313.98 | D45: 317.78 | E45: 311.24 | F45: 321.32 | G45: 317.64 | H45: 199.28 | I45: 198.28 | J45: : | K45: :
A46: Montenegro | B46: 2.37 | C46: 2.42 | D46: 2.45 | E46: 2.43 | F46: 2.3 | G46: 2.28 | H46: 2.3 | I46: 2.31 | J46: : | K46: :
A47: North Macedonia | B47: 167.68 | C47: 160.78 | D47: 162.36 | E47: 160.22 | F47: 159.45 | G47: 161.47 | H47: 159.03 | I47: 156.15 | J47: 152.07 | K47: :
A48: Albania | B48: 148 | C48: : | D48: 140.1 | E48: 132.2 | F48: 131.26 | G48: 134.3 | H48: 132.8 | I48: 135.7 | J48: 126.13 | K48: :
A49: Serbia | B49: 1758 | C49: 1709.9 | D49: 1712.98 | E49: 1698.99 | F49: 1740.46 | G49: 1770.19 | H49: 1724.73 | I49: 1766.06 | J49: 1674.38 | K49: :
A50: Türkiye | B50: 11465 | C50: 11108 | D50: 10899 | E50: 10773 | F50: 11144 | G50: 11136 | H50: 11198 | I50: 11523 | J50: 11544 | K50: :
A51: Kosovo* | B51: 134.6 | C51: 120.7 | D51: 123.9 | E51: 124.2 | F51: 124.71 | G51: 124.48 | H51: 124.62 | I51: 124.68 | J51: : | K51: :
A53: Special value
A54: : | B54: not available

Sheet Sheet 2
A1: Data extracted on 26/09/2025 16:39:19 from [ESTAT]
A2: Dataset: | B2: Crop production in EU standard humidity [apro_cpsh1__custom_18188015]
A3: Last updated: | B3: 17/09/2025 23:00
A5: Time frequency | C5: Annual
A6: Crops | C6: Cereals for the production of grain (including seed)
A7: Structure of production | C7: Harvested production in EU standard humidity (1000 t)
A9: TIME | B9: 2016 | C9: 2017 | D9: 2018 | E9: 2019 | F9: 2020 | G9: 2021 | H9: 2022 | I9: 2023 | J9: 2024 | K9: 2025
A10: GEO (Labels)
A11: European Union (EU6-1958, EU9-1973, EU10-1981, EU12-1986, EU15-1995, EU25-2004, EU27-2007, EU28-2013, EU27-2020) | B11: 301811.62 | C11: 309993.16 | D11: 294878.81 | E11: 324584.04 | F11: 285670.97 | G11: 297654.87 | H11: 270844.14 | I11: 271644.81 | J11: : | K11: :
A12: European Union - 27 countries (from 2020) | B12: 280101.04 | C12: 287259.62 | D12: 274038.99 | E12: 299364.18 | F12: 285670.97 | G12: 297654.87 | H12: 270844.14 | I12: 271644.81 | J12: : | K12: :
A13: European Union - 28 countries (2013-2020) | B13: 301811.62 | C13: 309993.16 | D13: 294878.81 | E13: 324584.04 | F13: : | G13: : | H13: : | I13: : | J13: : | K13: :
A14: Belgium | B14: 2228.79 | C14: 2642.25 | D14: 2431.04 | E14: 2816.04 | F14: 2565.7 | G14: 2452.66 | H14: 2780.16 | I14: 2755.95 | J14: 2039.71 | K14: :
A15: Bulgaria | B15: 8945.12 | C15: 9737.28 | D15: 10110.55 | E15: 11131.81 | F15: 8599.06 | G15: 11639.98 | H15: 9791.43 | I15: 10346.39 | J15: 10094.53 | K15: :
A16: Czechia | B16: 8596.41 | C16: 7456.78 | D16: 6970.92 | E16: 7646.15 | F16: 8126.66 | G16: 8227.11 | H16: 8218.42 | I16: 7995.52 | J16: 7520.79 | K16: :
A17: Denmark | B17: 9024.03 | C17: 9882.96 | D17: 6923.84 | E17: 9517.92 | F17: 9467.62 | G17: 8640.05 | H17: 9464.06 | I17: 7002.02 | J17: 7496.36 | K17: :
A18: Germany | B18: 45401 | C18: 45593.2 | D18: 37974.8 | E18: 44329.3 | F18: 43301.2 | G18: 42397.6 | H18: 43520.8 | I18: 42507.7 | J18: 39052.4 | K18: :
A19: Estonia | B19: 934.1 | C19: 1311.9 | D19: 919.83 | E19: 1624.58 | F19: 1632.79 | G19: 1285.75 | H19: 1528.55 | I19: 1200.67 | J19: 1303.53 | K19: :
A20: Ireland | B20: 2184.32 | C20: 2259.53 | D20: 1784.91 | E20: 2268 | F20: 1892.63 | G20: 2363.97 | H20: 2485.69 | I20: 1902.27 | J20: 1884.61 | K20: :
A21: Greece | B21: 3983.13 | C21: 3015.72 | D21: 2996.56 | E21: 2946.78 | F21: 3108.73 | G21: 3236.56 | H21: 3205.86 | I21: 3406.25 | J21: 2383.29 | K21: :
A22: Spain | B22: 24955.45 | C22: 17188.44 | D22: 25358.14 | E22: 20598.15 | F22: 27329.48 | G22: 25517.6 | H22: 19296.3 | I22: 11932.16 | J22: 21261.96 | K22: :
A23: France | B23: 53560.42 | C23: 67728.63 | D23: 61840.31 | E23: 70379.86 | F23: 57086.04 | G23: 66877.88 | H23: 59928.23 | I23: 64241.6 | J23: 53621.45 | K23: :
A24: Croatia | B24: 3554.43 | C24: 2678.79 | D24: 3268.48 | E24: 3540.05 | F24: 3774.57 | G24: 3671.23 | H24: 3042.9 | I24: 3214.16 | J24: 3320.37 | K24: :
A25: Italy | B25: 18363.1 | C25: 16554.95 | D25: 16615.46 | E25: 16433.5 | F25: 17022.9 | G25: 16632.66 | H25: 14337.92 | I25: 15505.27 | J25: : | K25: :
A26: Cyprus | B26: 10.42 | C26: 36.45 | D26: 24.71 | E26: 59.03 | F26: 60.96 | G26: 52.49 | H26: 55.84 | I26: 48.53 | J26: 45.42 | K26: :
A27: Latvia | B27: 2703.2 | C27: 2692.5 | D27: 2057.3 | E27: 3163.2 | F27: 3497.1 | G27: 2994.6 | H27: 3243.7 | I27: 2715.9 | J27: 3152.4 | K27: :
A28: Lithuania | B28: 5120.82 | C28: 5074.19 | D28: 3999.5 | E28: 5207.89 | F28: 6544.69 | G28: 5340.82 | H28: 5623.66 | I28: 5629.74 | J28: 5707.7 | K28: :
A29: Luxembourg | B29: 139.43 | C29: 149.81 | D29: 157.65 | E29: 163.56 | F29: 146.17 | G29: 147.17 | H29: 170.66 | I29: 148 | J29: 140.77 | K29: :
A30: Hungary | B30: 16594.35 | C30: 13979.39 | D30: 14890.26 | E30: 15643.37 | F30: 15561.08 | G30: 13969.54 | H30: 9055.71 | I30: 15041.14 | J30: 12788.41 | K30: :
A31: Malta | B31: 0 | C31: 0 | D31: 0 | E31: 0 | F31: 0 | G31: 0 | H31: 0 | I31: 0 | J31: 0 | K31: :
A32: Netherlands | B32: 1344.3 | C32: 1370.62 | D32: 1315.25 | E32: 1541.91 | F32: 1364.38 | G32: 1336.32 | H32: 1647.13 | I32: 1497.31 | J32: 1039.52 | K32: :
A33: Austria | B33: 5671.46 | C33: 4847.27 | D33: 4785.62 | E33: 5398.03 | F33: 5648.26 | G33: 5318.08 | H33: 5206.57 | I33: 5235.05 | J33: 4880.42 | K33: :
A34: Poland | B34: 29293.87 | C34: 31331.01 | D34: 26281.55 | E34: 28450.92 | F34: 35031.3 | G34: 33996.28 | H34: 34987.75 | I34: 35183.86 | J34: 34345.78 | K34: :
A35: Portugal | B35: 1152.27 | C35: 1137.5 | D35: 1116.32 | E35: 1163.02 | F35: 1055.08 | G35: 1127.7 | H35: 1019.9 | I35: 1044.51 | J35: 1001.38 | K35: :
A36: Romania | B36: 21764.82 | C36: 27138.88 | D36: 31553.28 | E36: 30412.43 | F36: 18153.71 | G36: 27791.26 | H36: 18860.68 | I36: 20784.66 | J36: 19855.25 | K36: :
A37: Slovenia | B37: 638.06 | C37: 546.99 | D37: 596.66 | E37: 641.74 | F37: 749.69 | G37: 700.55 | H37: 576.19 | I37: 666.89 | J37: 672.22 | K37: :
... A41: Iceland | B41: 6 | C41: 8 | D41: 3.95 | E41: 4.94 | F41: 7.22 | G41: 7.41 | H41: 9.29 | I41: 7.61 | J41: 4.15 | K41: :
A42: Norway | B42: 1310.58 | C42: 1292.08 | D42: 734.4 | E42: 1281.37 | F42: 1311 | G42: 1170.88 | H42: 1309.59 | I42: 775.87 | J42: : | K42: :
A43: Switzerland | B43: 752.06 | C43: 986.72 | D43: 891.58 | E43: 942.73 | F43: 1021.3 | G43: 791.47 | H43: 863.86 | I43: 807.87 | J43: 629.61 | K43: :
A44: United Kingdom | B44: 21710.58 | C44: 22733.55 | D44: 20839.83 | E44: 25219.86 | F44: 19469.45 | G44: : | H44: : | I44: : | J44: : | K44: :
A45: Bosnia and Herzegovina | B45: 1677.52 | C45: 1176.89 | D45: 1764.1 | E45: 1685.56 | F45: 1966.78 | G45: 1425.13 | H45: 1173.65 | I45: 1109.99 | J45: : | K45: :
...

Sheet Sheet 3
A1: Data extracted on 26/09/2025 16:39:19 from [ESTAT]
A2: Dataset: | B2: Crop production in EU standard humidity [apro_cpsh1__custom_18188015]
A3: Last updated: | B3: 17/09/2025 23:00
A5: Time frequency | C5: Annual
A6: Crops | C6: Cereals for the production of grain (including seed)
A7: Structure of production | C7: Yield in EU standard humidity (tonne/ha)
A9: TIME | B9: 2016 | C9: 2017 | D9: 2018 | E9: 2019 | F9: 2020 | G9: 2021 | H9: 2022 | I9: 2023 | J9: 2024 | K9: 2025
A10: GEO (Labels)
A11: European Union (EU6-1958, EU9-1973, EU10-1981, EU12-1986, EU15-1995, EU25-2004, EU27-2007, EU28-2013, EU27-2020) | B11: : | C11: : | D11: : | E11: : | F11: : | G11: : | H11: : | I11: : | J11: : | K11: :
A12: European Union - 27 countries (from 2020) | B12: : | C12: : | D12: : | E12: : | F12: : | G12: : | H12: : | I12: : | J12: : | K12: :
A13: European Union - 28 countries (2013-2020) | B13: : | C13: : | D13: : | E13: : | F13: : | G13: : | H13: : | I13: : | J13: : | K13: :
A14: Belgium | B14: : | C14: : | D14: : | E14: : | F14: : | G14: : | H14: : | I14: : | J14: : | K14: :
A15: Bulgaria | B15: : | C15: : | D15: : | E15: : | F15: : | G15: : | H15: : | I15: : | J15: : | K15: :
A16: Czechia | B16: : | C16: : | D16: : | E16: : | F16: : | G16: : | H16: : | I16: : | J16: : | K16: :
A17: Denmark | B17: : | C17: : | D17: : | E17: : | F17: : | G17: : | H17: : | I17: : | J17: : | K17: :
A18: Germany | B18: : | C18: : | D18: : | E18: : | F18: : | G18: : | H18: : | I18: : | J18: : | K18: :
A19: Estonia | B19: : | C19: : | D19: : | E19: : | F19: : | G19: : | H19: : | I19: : | J19: : | K19: :
A20: Ireland | B20: : | C20: : | D20: : | E20: : | F20: : | G20: : | H20: : | I20: : | J20: : | K20: :
A21: Greece | B21: : | C21: : | D21: : | E21: : | F21: : | G21: : | H21: : | I21: : | J21: : | K21: :
A22: Spain | B22: : | C22: : | D22: : | E22: : | F22: : | G22: : | H22: : | I22: : | J22: : | K22: :
... A51: Kosovo* | B51: : | C51: : | D51: : | E51: : | F51: : | G51: : | H51: : | I51: : | J51: : | K51: :
A53: Special value
A54: : | B54: not available

Sheet Sheet 4
A1: Data extracted on 26/09/2025 16:39:19 from [ESTAT]
A2: Dataset: | B2: Crop production in EU standard humidity [apro_cpsh1__custom_18188015]
A3: Last updated: | B3: 17/09/2025 23:00
A5: Time frequency | C5: Annual
A6: Crops | C6: Cereals (excluding rice) for the production of grain (including seed)
A7: Structure of production | C7: Area (cultivation/harvested/production) (1000 ha)
A9: TIME | B9: 2016 | C9: 2017 | D9: 2018 | E9: 2019 | F9: 2020 | G9: 2021 | H9: 2022 | I9: 2023 | J9: 2024 | K9: 2025
A10: GEO (Labels)
A11: European Union (EU6-1958, EU9-1973, EU10-1981, EU12-1986, EU15-1995, EU25-2004, EU27-2007, EU28-2013, EU27-2020) | B11: 56754.8 | C11: 55179.81 | D11: 55019.64 | E11: 56451.43 | F11: 51826.04 | G11: 52128.31 | H11: 51115.93 | I11: 50616.79 | J11: 49021.3 | K11: :
A12: European Union - 27 countries (from 2020) | B12: 53626.8 | C12: 51998.41 | D12: 51913.84 | E12: 53240.57 | F12: 51826.04 | G12: 52128.31 | H12: 51115.93 | I12: 50616.79 | J12: 49021.3 | K12: :
A13: European Union - 28 countries (2013-2020) | B13: 56754.8 | C13: 55179.81 | D13: 55019.64 | E13: 56451.43 | F13: : | G13: : | H13: : | I13: : | J13: : | K13: :
A14: Belgium | B14: 337.02 | C14: 305.43 | D14: 304.52 | E14: 313.11 | F14: 304.34 | G14: 310.2 | H14: 323.07 | I14: 324.66 | J14: 281.94 | K14: :
A15: Bulgaria | B15: 1804.65 | C15: 1718.83 | D15: 1806.78 | E15: 1915.74 | F15: 1953.69 | G15: 1944.28 | H15: 1890.08 | I15: 1969.25 | J15: 1956.03 | K15: :
A16: Czechia | B16: 1359.01 | C16: 1354.68 | D16: 1338.78 | E16: 1352.53 | F16: 1344.88 | G16: 1345.84 | H16: 1386.01 | I16: 1317.2 | J16: 1307.64 | K16: :
A17: Denmark | B17: 1464.8 | C17: 1442.8 | D17: 1416.29 | E17: 1373.66 | F17: 1366.92 | G17: 1359.58 | H17: 1306.95 | I17: 1234.53 | J17: 1229.65 | K17: :
A18: Germany | B18: 6325 | C18: 6276.2 | D18: 6148.9 | E18: 6380 | F18: 6074.9 | G18: 6063.5 | H18: 6112.5 | I18: 6076.2 | J18: 5757.9 | K18: :
A19: Estonia | B19: 351.4 | C19: 330.68 | D19: 350.43 | E19: 364.36 | F19: 370.12 | G19: 367.12 | H19: 361.82 | I19: 352.15 | J19: 349.19 | K19: :
A20: Ireland | B20: 280.34 | C20: 271.68 | D20: 260.97 | E20: 266.66 | F20: 265.63 | G20: 274.66 | H20: 285.66 | I20: 269.36 | J20: 259.18 | K20: :
A21: Greece | B21: 952.81 | C21: 808.22 | D21: 757.63 | E21: 698.29 | F21: 703.79 | G21: 736.01 | H21: 744.49 | I21: 794.67 | J21: 558.34 | K21: :
A22: Spain | B22: 6130.53 | C22: 5907.63 | D22: 5922.6 | E22: 5872.34 | F22: 5967.17 | G22: 5949.9 | H22: 5776.95 | I22: 5389.38 | J22: 5388.16 | K22: :
A23: France | B23: 9513.27 | C23: 9323.15 | D23: 9042.03 | E23: 9378.93 | F23: 8912.36 | G23: 9313.68 | H23: 8993.25 | I23: 8819.42 | J23: 8523.96 | K23: :
A24: Croatia | B24: 508.66 | C24: 461.48 | D24: 459.7 | E24: 490.88 | F24: 535.76 | G24: 519.78 | H24: 519.28 | I24: 539.59 | J24: 495.7 | K24: :
A25: Italy | B25: 3022.86 | C25: 2906.45 | D25: 2875.5 | E25: 2846.49 | F25: 2784.41 | G25: 2751.36 | H25: 2792.21 | I25: 2844.05 | J25: 2611.37 | K25: :
... A41: Iceland | B41: 2 | C41: 2 | D41: 1.5 | E41: 2 | F41: 2.8 | G41: 2.6 | H41: 3.16 | I41: 2.95 | J41: 2.7 | K41: :
A42: Norway | B42: 285.1 | C42: 286.79 | D42: 279.98 | E42: 275.55 | F42: 280.22 | G42: 283.5 | H42: 280.61 | I42: 283.88 | J42: : | K42: :
A43: Switzerland | B43: 144.02 | C43: 143.25 | D43: 141.64 | E43: 141.36 | F43: 144.45 | G43: 141.62 | H43: 141.77 | I43: 141.3 | J43: 136.22 | K43: :
A44: United Kingdom | B44: 3128 | C44: 3181.4 | D44: 3105.8 | E44: 3210.86 | F44: 3093.38 | G44: : | H44: : | I44: : | J44: : | K44: :
A45: Bosnia and Herzegovina | B45: 313.59 | C45: 313.98 | D45: 317.78 | E45: 311.24 | F45: 321.32 | G45: 317.64 | H45: 199.28 | I45: 198.28 | J45: : | K45: :
A46: Montenegro | B46: 2.37 | C46: 2.42 | D46: 2.45 | E46: 2.43 | F46: 2.3 | G46: 2.28 | H46: 2.3 | I46: 2.31 | J46: : | K46: :
A47: North Macedonia | B47: 162.64 | C47: 157.5 | D47: 159.14 | E47: 156.74 | F47: 156.27 | G47: 158.36 | H47: 155.92 | I47: 152.99 | J47: 148.95 | K47: :
A48: Albania | B48: 148 | C48: 145.8 | D48: 140.1 | E48: 132.2 | F48: : | G48: : | H48: : | I48: : | J48: : | K48: :
A49: Serbia | B49: 1758 | C49: 1709.9 | D49: 1712.9 | E49: 1698.99 | F49: 1740.46 | G49: 1770.19 | H49: 1724.74 | I49: 1766.06 | J49: 1674.38 | K49: :
A50: Türkiye | B50: 11349 | C50: 10998 | D50: 10779 | E50: 10647 | F50: 11019 | G50: 11008 | H50: 11080 | I50: 11412 | J50: 11416 | K50: :
A51: Kosovo* | B51: 134.6 | C51: 120.7 | D51: 123.9 | E51: 124.2 | F51: : | G51: 124.48 | H51: 124.62 | I51: 124.68 | J51: : | K51: :
A53: Special value
A54: : | B54: not available

Sheet Sheet 5
A1: Data extracted on 26/09/2025 16:39:19 from [ESTAT]
A2: Dataset: | B2: Crop production in EU standard humidity [apro_cpsh1__custom_18188015]
A3: Last updated: | B3: 17/09/2025 23:00
A5: Time frequency | C5: Annual
A6: Crops | C6: Cereals (excluding rice) for the production of grain (including seed)
A7: Structure of production | C7: Harvested production in EU standard humidity (1000 t)
A9: TIME | B9: 2016 | C9: 2017 | D9: 2018 | E9: 2019 | F9: 2020 | G9: 2021 | H9: 2022 | I9: 2023 | J9: 2024 | K9: 2025
A10: GEO (Labels)
A11: European Union (EU6-1958, EU9-1973, EU10-1981, EU12-1986, EU15-1995, EU25-2004, EU27-2007, EU28-2013, EU27-2020) | B11: 298938.9 | C11: 306965.07 | D11: 291990.94 | E11: 321678.38 | F11: 282779.14 | G11: 294937.89 | H11: 268699.11 | I11: 269370.58 | J11: 257011.04 | K11: :
A12: European Union - 27 countries (from 2020) | B12: 277228.32 | C12: 284231.53 | D12: 271151.11 | E12: 296458.54 | F12: 282779.14 | G12: 294937.89 | H12: 268699.11 | I12: 269370.58 | J12: 257011.04 | K12: :
A13: European Union - 28 countries (2013-2020) | B13: 298938.9 | C13: 306965.07 | D13: 291990.94 | E13: 321678.38 | F13: : | G13: : | H13: : | I13: : | J13: : | K13: :
A14: Belgium | B14: 2228.79 | C14: 2642.24 | D14: 2431.04 | E14: 2816.04 | F14: 2565.69 | G14: 2452.66 | H14: 2780.16 | I14: 2755.94 | J14: 2039.71 | K14: :
A15: Bulgaria | B15: 8881.85 | C15: 9676.98 | D15: 10049.13 | E15: 11060.07 | F15: 8532.49 | G15: 11581.18 | H15: 9726.36 | I15: 10281.49 | J15: 10027.92 | K15: :
A16: Czechia | B16: 8596.41 | C16: 7456.78 | D16: 6970.92 | E16: 7646.15 | F16: 8126.66 | G16: 8227.11 | H16: 8218.42 | I16: 7995.52 | J16: 7520.79 | K16: :
A17: Denmark | B17: 9024.05 | C17: 9882.96 | D17: 6923.9 | E17: 9517.81 | F17: 9467.71 | G17: 8640.06 | H17: 9464.18 | I17: 7001.95 | J17: 7496.36 | K17: :
A18: Germany | B18: 45401 | C18: 45593.2 | D18: 37974.8 | E18: 44329.3 | F18: 43301.2 | G18: 42397.6 | H18: 43520.8 | I18: 42507.7 | J18: 39052.4 | K18: :
A19: Estonia | B19: 934.1 | C19: 1311.9 | D19: 919.83 | E19: 1624.58 | F19: 1632.79 | G19: 1285.75 | H19: 1528.55 | I19: 1200.67 | J19: 1303.53 | K19: :
A20: Ireland | B20: 2184.32 | C20: 2259.53 | D20: 1784.91 | E20: 2268 | F20: 1892.63 | G20: 2363.97 | H20: 2485.69 | I20: 1902.27 | J20: 1884.61 | K20: :
A21: Greece | B21: 3803.79 | C21: 2836.25 | D21: 2771.28 | E21: 2723.28 | F21: 2817.97 | G21: 2988.36 | H21: 2988.62 | I21: 3213.6 | J21: 2256.74 | K21: :
A22: Spain | B22: 24120.16 | C22: 16353.2 | D22: 24549.99 | E22: 19810.23 | F22: 26581.85 | G22: 24893.34 | H22: 18941.81 | I22: 11594.18 | J22: 20699.66 | K22: :
A23: France | B23: 53481.05 | C23: 67637.16 | D23: 61768.05 | E23: 70296.33 | F23: 57009.71 | G23: 66785.16 | H23: 59863 | I23: 64172.54 | J23: 53548.63 | K23: :
A24: Croatia | B24: 3472.83 | C24: 2678.79 | D24: 3268.48 | E24: 3540.05 | F24: 3774.57 | G24: 3671.23 | H24: 3042.9 | I24: 3214.16 | J24: 3320.37 | K24: :
A25: Italy | B25: 17057.16 | C25: 14928.71 | D25: 15114.05 | E25: 14909.02 | F25: 15483.29 | G25: 15142.27 | H25: 13079.29 | I25: 14097.25 | J25: 12711.09 | K25: :
... A41: Iceland | B41: 6 | C41: 8 | D41: 4 | E41: 5 | F41: 7.22 | G41: 7.41 | H41: 9.29 | I41: 7.61 | J41: 4.15 | K41: :
A42: Norway | B42: : | C42: 1292.08 | D42: 734.39 | E42: 1281.33 | F42: 1311 | G42: 1170.88 | H42: 1309.59 | I42: 775.87 | J42: : | K42: :
A43: Switzerland | B43: 751.65 | C43: 986.35 | D43: 891.15 | E43: 942.29 | F43: 1020.85 | G43: 791.23 | H43: 863.61 | I43: 807.58 | J43: 629.37 | K43: :
A44: United Kingdom | B44: 21710.58 | C44: 22733.55 | D44: 20839.83 | E44: 25219.85 | F44: 19469.45 | G44: : | H44: : | I44: : | J44: : | K44: :
A45: Bosnia and Herzegovina | B45: 1677.52 | C45: 1176.89 | D45: 1764.1 | E45: 1685.56 | F45: 1966.78 | G45: 1425.13 | H45: 1173.65 | I45: 1109.99 | J45: : | K45: :
A46: Montenegro | B46: 7.69 | C46: 7.87 | D46: 8.02 | E46: 7.58 | F46: 7.28 | G46: 7.1 | H46: 7.2 | I46: 7.69 | J46: : | K46: :
A47: North Macedonia | B47: 623.28 | C47: 435.64 | D47: 585.3 | E47: 548.07 | F47: 565.75 | G47: 549.69 | H47: 529.2 | I47: 508.75 | J47: 519.43 | K47: :
A48: Albania | B48: 698.4 | C48: : | D48: 678.2 | E48: 666.1 | F48: : | G48: 691.4 | H48: : | I48: : | J48: : | K48: :
A49: Serbia | B49: 10868 | C49: 6793.3 | D49: 10528.98 | E49: 10436.43 | F49: 11447.57 | G49: 10236.39 | H49: 8012.86 | I49: 10809.34 | J49: 8687.11 | K49: :
A50: Türkiye | B50: 35160.09 | C50: 36052.37 | D50: 34130.6 | E50: 34177.77 | F50: 37046.98 | G50: 31579.72 | H50: 38591.07 | I50: 42254.33 | J50: 38878.6 | K50: :
A51: Kosovo* | B51: 562.9 | C51: 477.9 | D51: 441.8 | E51: 459.4 | F51: : | G51: 504.37 | H51: 518.72 | I51: 477.15 | J51: : | K51: :
A53: Special value
A54: : | B54: not available

Sheet Sheet 6
A1: Data extracted on 26/09/2025 16:39:19 from [ESTAT]
A2: Dataset: | B2: Crop production in EU standard humidity [apro_cpsh1__custom_18188015]
A3: Last updated: | B3: 17/09/2025 23:00
A5: Time frequency | C5: Annual
A6: Crops | C6: Cereals (excluding rice) for the production of grain (including seed)
A7: Structure of production | C7: Yield in EU standard humidity (tonne/ha)
A9: TIME | B9: 2016 | C9: 2017 | D9: 2018 | E9: 2019 | F9: 2020 | G9: 2021 | H9: 2022 | I9: 2023 | J9: 2024 | K9: 2025
A10: GEO (Labels)
A11: European Union (EU6-1958, EU9-1973, EU10-1981, EU12-1986, EU15-1995, EU25-2004, EU27-2007, EU28-2013, EU27-2020) | B11: : | C11: : | D11: : | E11: : | F11: : | G11: : | H11: : | I11: : | J11: : | K11: :
A12: European Union - 27 countries (from 2020) | B12: : | C12: : | D12: : | E12: : | F12: : | G12: : | H12: : | I12: : | J12: : | K12: :
A13: European Union - 28 countries (2013-2020) | B13: : | C13: : | D13: : | E13: : | F13: : | G13: : | H13: : | I13: : | J13: : | K13: :
A14: Belgium | B14: : | C14: : | D14: : | E14: : | F14: : | G14: : | H14: : | I14: : | J14: : | K14: :
A15: Bulgaria | B15: : | C15: : | D15: : | E15: : | F15: : | G15: : | H15: : | I15: : | J15: : | K15: :
A16: Czechia | B16: : | C16: : | D16: : | E16: : | F16: : | G16: : | H16: : | I16: : | J16: : | K16: :
A17: Denmark | B17: : | C17: : | D17: : | E17: : | F17: : | G17: : | H17: : | I17: : | J17: : | K17: :
A18: Germany | B18: : | C18: : | D18: : | E18: : | F18: : | G18: : | H18: : | I18: : | J18: : | K18: :
A19: Estonia | B19: : | C19: : | D19: : | E19: : | F19: : | G19: : | H19: : | I19: : | J19: : | K19: :
A20: Ireland | B20: : | C20: : | D20: : | E20: : | F20: : | G20: : | H20: : | I20: : | J20: : | K20: :
A21: Greece | B21: : | C21: : | D21: : | E21: : | F21: : | G21: : | H21: : | I21: : | J21: : | K21: :
A22: Spain | B22: : | C22: : | D22: : | E22: : | F22: : | G22: : | H22: : | I22: : | J22: : | K22: :
... A51: Kosovo* | B51: : | C51: : | D51: : | E51: : | F51: : | G51: : | H51: : | I51: : | J51: : | K51: :
A53: Special value
A54: : | B54: not available

Sheet Sheet 7
A1: Data extracted on 26/09/2025 16:39:19 from [ESTAT]
A2: Dataset: | B2: Crop production in EU standard humidity [apro_cpsh1__custom_18188015]
A3: Last updated: | B3: 17/09/2025 23:00
A5: Time frequency | C5: Annual
A6: Crops | C6: Wheat and spelt
A7: Structure of production | C7: Area (cultivation/harvested/production) (1000 ha)
A9: TIME | B9: 2016 | C9: 2017 | D9: 2018 | E9: 2019 | F9: 2020 | G9: 2021 | H9: 2022 | I9: 2023 | J9: 2024 | K9: 2025
A10: GEO (Labels)
A11: European Union (EU6-1958, EU9-1973, EU10-1981, EU12-1986, EU15-1995, EU25-2004, EU27-2007, EU28-2013, EU27-2020) | B11: 27033.3 | C11: 25930.62 | D11: 25499.36 | E11: 26028.08 | F11: 22775.8 | G11: 24076.38 | H11: 24213.51 | I11: 24232.8 | J11: 22286.18 | K11: :
A12: European Union - 27 countries (from 2020) | B12: 25210.3 | C12: 24138.62 | D12: 23751.66 | E12: 24212.28 | F12: 22775.8 | G12: 24076.38 | H12: 24213.51 | I12: 24232.8 | J12: 22286.18 | K12: :
A13: European Union - 28 countries (2013-2020) | B13: 27033.3 | C13: 25930.62 | D13: 25499.36 | E13: 26028.08 | F13: : | G13: : | H13: : | I13: : | J13: : | K13: :
A14: Belgium | B14: 215.72 | C14: 197.59 | D14: 195.69 | E14: 203.76 | F14: 194.66 | G14: 209.18 | H14: 204.46 | I14: 212.61 | J14: 164.54 | K14: 198.13
A15: Bulgaria | B15: 1192.59 | C15: 1144.52 | D15: 1212.01 | E15: 1198.68 | F15: 1200.18 | G15: 1206.19 | H15: 1206.58 | I15: 1220.91 | J15: 1194.34 | K15: 1266
A16: Czechia | B16: 839.71 | C16: 832.06 | D16: 819.69 | E16: 839.45 | F16: 798.58 | G16: 784.78 | H16: 854.43 | I16: 817.76 | J16: 776.5 | K16: 785.03
A17: Denmark | B17: 583 | C17: 586.6 | D17: 425.8 | E17: 573.4 | F17: 502.6 | G17: 537.7 | H17: 497.3 | I17: 489 | J17: 475.6 | K17: 473.78
A18: Germany | B18: 3201.7 | C18: 3202.6 | D18: 3036.3 | E18: 3118.1 | F18: 2835.5 | G18: 2939 | H18: 2980.9 | I18: 2897.8 | J18: 2615.2 | K18: 2959.1
A19: Estonia | B19: 164.5 | C19: 169.75 | D19: 154.58 | E19: 166.98 | F19: 168.04 | G19: 180 | H19: 180.97 | I19: 173.57 | J19: 173.32 | K19: :
A20: Ireland | B20: 67.92 | C20: 67.05 | D20: 57.98 | E20: 63.48 | F20: 46.99 | G20: 62.33 | H20: 67.23 | I20: 55.78 | J20: 47.8 | K20: 64.09
A21: Greece | B21: 537.59 | C21: 415.95 | D21: 404.49 | E21: 350.49 | F21: 355.88 | G21: 411.01 | H21: 412.49 | I21: 448.46 | J21: 264.08 | K21: 439.79
A22: Spain | B22: 2256.85 | C22: 2062.71 | D22: 2063.68 | E22: 1920.09 | F22: 1914.66 | G22: 2128.47 | H22: 2172.7 | I22: 1957.76 | J22: 1939.02 | K22: 2024.31
A23: France | B23: 5542.25 | C23: 5332.08 | D23: 5234.09 | E23: 5244.25 | F23: 4519.78 | G23: 5276.73 | H23: 4949.84 | I23: 4998.28 | J23: 4457.41 | K23: 4706.03
A24: Croatia | B24: 171.4 | C24: 118.38 | D24: 138.46 | E24: 143.15 | F24: 147.84 | G24: 147.39 | H24: 161.83 | I24: 172.85 | J24: 138 | K24: 152.5
A25: Italy | B25: 1912.42 | C25: 1806.57 | D25: 1821.73 | E25: 1754.64 | F25: 1711.22 | G25: 1726.61 | H25: 1776.73 | I25: 1867.56 | J25: 1697.75 | K25: 1645.34
A26: Cyprus | B26: 8.39 | C26: 8.68 | D26: 10.2 | E26: 10.59 | F26: 12.97 | G26: 12.32 | H26: 13.31 | I26: 14.13 | J26: 12.25 | K26: :
A27: Latvia | B27: 479.1 | C27: 446.8 | D27: 417.2 | E27: 492.7 | F27: 498.2 | G27: 537.3 | H27: 537.5 | I27: 525 | J27: 540 | K27: 545.6
A28: Lithuania | B28: 880.53 | C28: 811.95 | D28: 772.89 | E28: 895.76 | F28: 893.51 | G28: 944.17 | H28: 946.72 | I28: 940.29 | J28: 836.97 | K28: 829.95
A29: Luxembourg | B29: 13.81 | C29: 14.11 | D29: 12.87 | E29: 13.36 | F29: 11.93 | G29: 12.87 | H29: 13.57 | I29: 12.47 | J29: 12.71 | K29: :
A30: Hungary | B30: 1044.31 | C30: 966.4 | D30: 1026.15 | E30: 1015.64 | F30: 936.62 | G30: 892.79 | H30: 979.01 | I30: 1053.12 | J30: 921.89 | K30: 1057.18
A31: Malta | B31: 0 | C31: 0 | D31: 0 | E31: 0 | F31: 0 | G31: 0 | H31: 0 | I31: 0 | J31: 0 | K31: :
A32: Netherlands | B32: 127.33 | C32: 115.92 | D32: 111.66 | E32: 120.55 | F32: 108.91 | G32: 118.14 | H32: 123.8 | I32: 129.54 | J32: 95.85 | K32: 112.71
A33: Austria | B33: 317.76 | C33: 297.28 | D33: 294.29 | E33: 278.34 | F33: 279.02 | G33: 279.86 | H33: 295.51 | I33: 281.98 | J33: 274.23 | K33: 280.92
A34: Poland | B34: 2364.08 | C34: 2391.85 | D34: 2417.23 | E34: 2511.33 | F34: 2391 | G34: 2390.52 | H34: 2518.44 | I34: 2449.33 | J34: 2385.69 | K34: 2423.12
A35: Portugal | B35: 38.2 | C35: 29.02 | D35: 27.03 | E35: 28.53 | F35: 30.14 | G35: 28.66 | H35: 31.05 | I35: 24.74 | J35: 26.51 | K35: 25.88
A36: Romania | B36: 2137.73 | C36: 2052.92 | D36: 2116.15 | E36: 2168.37 | F36: 2155.25 | G36: 2175.08 | H36: 2168.66 | I36: 2317.69 | J36: 2204.1 | K36: 2308.22
A37: Slovenia | B37: 31.46 | C37: 28.02 | D37: 27.82 | E37: 26.73 | F37: 27.29 | G37: 26.79 | H37: 27.56 | I37: 28.71 | J37: 27.98 | K37: :
A38: Slovakia | B38: 417.71 | C38: 373.67 | D38: 403.37 | E38: 406.82 | F38: 387.08 | G38: 356.97 | H38: 411.69 | I38: 406.76 | J38: 314.75 | K38: 380.8
A39: Finland | B39: 215.1 | C39: 194.28 | D39: 177.8 | E39: 197.6 | F39: 198.8 | G39: 212.4 | H39: 219.64 | I39: 229.16 | J39: 214.75 | K39: 227.17
A40: Sweden | B40: 449.15 | C40: 471.87 | D40: 372.5 | E40: 469.49 | F40: 449.17 | G40: 479.13 | H40: 461.57 | I40: 507.53 | J40: 474.94 | K40: 527.6
A41: Iceland | B41: 0 | C41: 0 | D41: 0 | E41: 0 | F41: 0 | G41: 0.1 | H41: 0.06 | I41: 0.05 | J41: 0.05 | K41: :
A42: Norway | B42: 66.8 | C42: 75.75 | D42: : | E42: : | F42: : | G42: : | H42: : | I42: : | J42: : | K42: :
...

Sheet Sheet 8
A1: Data extracted on 26/09/2025 16:39:20 from [ESTAT]
A2: Dataset: | B2: Crop production in EU standard humidity [apro_cpsh1__custom_18188015]
A3: Last updated: | B3: 17/09/2025 23:00
A5: Time frequency | C5: Annual
A6: Crops | C6: Wheat and spelt
A7: Structure of production | C7: Harvested production in EU standard humidity (1000 t)
A9: TIME | B9: 2016 | C9: 2017 | D9: 2018 | E9: 2019 | F9: 2020 | G9: 2021 | H9: 2022 | I9: 2023 | J9: 2024 | K9: 2025
A10: GEO (Labels)
A11: European Union (EU6-1958, EU9-1973, EU10-1981, EU12-1986, EU15-1995, EU25-2004, EU27-2007, EU28-2013, EU27-2020) | B11: 144745.44 | C11: 151549.89 | D11: 137908.11 | E11: 155468.03 | F11: 126418.09 | G11: 138180.51 | H11: 134304.18 | I11: 133481.17 | J11: 119943.94 | K11: :
A12: European Union - 27 countries (from 2020) | B12: 130529.68 | C12: 136885.41 | D12: 124510.72 | E12: 139432.18 | F12: 126418.09 | G12: 138180.51 | H12: 134304.18 | I12: 133481.17 | J12: 119943.94 | K12: :
A13: European Union - 28 countries (2013-2020) | B13: 144745.44 | C13: 151549.89 | D13: 137908.11 | E13: 155468.03 | F13: : | G13: : | H13: : | I13: : | J13: : | K13: :
A14: Belgium | B14: 1431.44 | C14: 1690.84 | D14: 1661.86 | E14: 1902.38 | F14: 1741.48 | G14: 1629.18 | H14: 1851.87 | I14: 1791.17 | J14: 1085.38 | K14: 1421.58
A15: Bulgaria | B15: 5942.78 | C15: 6318.08 | D15: 5954.52 | E15: 6319.63 | F15: 4847.94 | G15: 7342.99 | H15: 6447.77 | I15: 6854.76 | J15: 7084.75 | K15: 7573.28
A16: Czechia | B16: 5454.66 | C16: 4718.21 | D16: 4417.84 | E16: 4812.16 | F16: 4902.41 | G16: 4960.93 | H16: 5188.69 | I16: 5262.36 | J16: 4625.37 | K16: 4776.83
A17: Denmark | B17: 4152.65 | C17: 4777.89 | D17: 2623.93 | E17: 4642.09 | F17: 4070.41 | G17: 4047.09 | H17: 4165.4 | I17: 3556.26 | J17: 3348.01 | K17: 4073.47
A18: Germany | B18: 24463.8 | C18: 24481.6 | D18: 20263.5 | E18: 23062.6 | F18: 22172.1 | G18: 21459.2 | H18: 22587.3 | I18: 21535.9 | J18: 18526.7 | K18: 21571
A19: Estonia | B19: 455.5 | C19: 713.26 | D19: 450.27 | E19: 846.58 | F19: 840.52 | G19: 736.27 | H19: 854.12 | I19: 694.12 | J19: 744.75 | K19: :
A20: Ireland | B20: 610.24 | C20: 634.4 | D20: 485.48 | E20: 595.36 | F20: 364.92 | G20: 628.08 | H20: 701.24 | I20: 483.11 | J20: 388.1 | K20: 650.45
A21: Greece | B21: 1665.35 | C21: 1023.9 | D21: 1072.94 | E21: 979.22 | F21: 1095.15 | G21: 1159.19 | H21: 1203.26 | I21: 1309.18 | J21: 832.9 | K21: 1277.49
A22: Spain | B22: 8199.69 | C22: 5033.04 | D22: 8322.51 | E22: 6041.17 | F22: 8143.51 | G22: 8564.63 | H22: 6508.8 | I22: 4049.23 | J22: 7431.41 | K22: 8469.09
A23: France | B23: 28975.44 | C23: 38228.15 | D23: 35424.14 | E23: 40604.96 | F23: 30181.14 | G23: 36559.45 | H23: 34632.38 | I23: 35995.57 | J23: 26546.26 | K23: 33935.45
A24: Croatia | B24: 969.05 | C24: 695.59 | D24: 753.06 | E24: 803.27 | F24: 867.53 | G24: 986.93 | H24: 971.47 | I24: 834.23 | J24: 815.37 | K24: 913.3
A25: Italy | B25: 8236.95 | C25: 7139.01 | D25: 7104.65 | E25: 6739.47 | F25: 6716.18 | G25: 7294.57 | H25: 6609.52 | I25: 6894.47 | J25: 6213.21 | K25: 6584.45
A26: Cyprus | B26: 7.1 | C26: 17.11 | D26: 15.33 | E26: 29.47 | F26: 34.65 | G26: 25.93 | H26: 31.1 | I26: 28.25 | J26: 25.27 | K26: :
A27: Latvia | B27: 2062.3 | C27: 2138.8 | D27: 1431.6 | E27: 2371 | F27: 2659.6 | G27: 2407.7 | H27: 2539.4 | I27: 2136.8 | J27: 2465.9 | K27: 2525.7
A28: Lithuania | B28: 3844.49 | C28: 3917.37 | D28: 2838.9 | E28: 3843.85 | F28: 4818.75 | G28: 4248.85 | H28: 4482.76 | I28: 4455.39 | J28: 4219.3 | K28: 3984.95
A29: Luxembourg | B29: 70.15 | C29: 77.55 | D29: 79.65 | E29: 82.26 | F29: 72.4 | G29: 76.14 | H29: 85.89 | I29: 72.36 | J29: 65.86 | K29: :
A30: Hungary | B30: 5603.18 | C30: 5246.26 | D30: 5258.43 | E30: 5377.71 | F30: 5121.48 | G30: 5290.14 | H30: 4354.71 | I30: 5941.99 | J30: 5338.73 | K30: 5821.44
A31: Malta | B31: 0 | C31: 0 | D31: 0 | E31: 0 | F31: 0 | G31: 0 | H31: 0 | I31: 0 | J31: 0 | K31: :
A32: Netherlands | B32: 995.2 | C32: 1032.21 | D32: 961.92 | E32: 1130.53 | F32: 931.83 | G32: 947.25 | H32: 1162.86 | I32: 1096.82 | J32: 668.17 | K32: 1136.65
A33: Austria | B33: 1965.54 | C33: 1434.38 | D33: 1367.06 | E33: 1596.88 | F33: 1652.74 | G33: 1547.6 | H33: 1712.53 | I33: 1744.82 | J33: 1576.01 | K33: 1740.44
A34: Poland | B34: 10626.45 | C34: 11448.66 | D34: 9637.62 | E34: 10807.49 | F34: 12515.06 | G34: 11893.55 | H34: 13195.12 | I34: 12932.39 | J34: 12183.62 | K34: 12591.69
A35: Portugal | B35: 93.16 | C35: 61.69 | D35: 70.11 | E35: 77.07 | F35: 83.5 | G35: 69.44 | H35: 61.92 | I35: 34.67 | J35: 66.44 | K35: 61.03
A36: Romania | B36: 8431.13 | C36: 10034.96 | D36: 10143.67 | E36: 10297.11 | F36: 6392.37 | G36: 10433.75 | H36: 8684.24 | I36: 9624.07 | J36: 10139 | K36: 13011.07
A37: Slovenia | B37: 163.17 | C37: 140.96 | D37: 121.9 | E37: 139.81 | F37: 158.18 | G37: 154.45 | H37: 150.75 | I37: 145.42 | J37: 153.02 | K37: :
A38: Slovakia | B38: 2434.22 | C38: 1770.66 | D38: 1927.93 | E38: 1939.13 | F38: 2133.33 | G38: 2002.24 | H38: 2048.15 | I38: 2490.6 | J38: 1715.06 | K38: 2298.2
A39: Finland | B39: 834.44 | C39: 812.24 | D39: 501.6 | E39: 914.18 | F39: 686.62 | G39: 687.16 | H39: 844.24 | I39: 749.03 | J39: 759.38 | K39: 977.76
A40: Sweden | B40: 2841.6 | C40: 3298.6 | D40: 1620.3 | E40: 3476.8 | F40: 3214.3 | G40: 3027.8 | H40: 3228.7 | I40: 2768.2 | J40: 2926 | K40: 3558.2
A41: Iceland | B41: 0 | C41: 0 | D41: 0 | E41: 0 | F41: 0 | G41: 0 | H41: 0.2 | I41: 0.1 | J41: 0.1 | K41: :
A42: Norway | B42: 305.79 | C42: 395.83 | D42: : | E42: : | F42: : | G42: : | H42: : | I42: 170 | J42: : | K42: :
...

Sheet Sheet 9
A1: Data extracted on 26/09/2025 16:39:20 from [ESTAT]
A2: Dataset: | B2: Crop production in EU standard humidity [apro_cpsh1__custom_18188015]
A3: Last updated: | B3: 17/09/2025 23:00
A5: Time frequency | C5: Annual
A6: Crops | C6: Wheat and spelt
A7: Structure of production | C7: Yield in EU standard humidity (tonne/ha)
A9: TIME | B9: 2016 | C9: 2017 | D9: 2018 | E9: 2019 | F9: 2020 | G9: 2021 | H9: 2022 | I9: 2023 | J9: 2024 | K9: 2025
A10: GEO (Labels)
A11: European Union (EU6-1958, EU9-1973, EU10-1981, EU12-1986, EU15-1995, EU25-2004, EU27-2007, EU28-2013, EU27-2020) | B11: : | C11: : | D11: : | E11: : | F11: : | G11: : | H11: : | I11: : | J11: : | K11: :
A12: European Union - 27 countries (from 2020) | B12: : | C12: : | D12: : | E12: : | F12: : | G12: : | H12: : | I12: : | J12: : | K12: :
A13: European Union - 28 countries (2013-2020) | B13: : | C13: : | D13: : | E13: : | F13: : | G13: : | H13: : | I13: : | J13: : | K13: :
A14: Belgium | B14: 6.64 | C14: 8.56 | D14: 8.49 | E14: 9.33 | F14: 8.95 | G14: 7.79 | H14: 9.05 | I14: 8.42 | J14: 6.58 | K14: 7.17
A15: Bulgaria | B15: 4.98 | C15: 5.52 | D15: 4.91 | E15: 5.27 | F15: 4.01 | G15: 6.09 | H15: : | I15: 5.59 | J15: 5.93 | K15: 5.98
A16: Czechia | B16: 6.5 | C16: 5.67 | D16: 5.39 | E16: 5.73 | F16: 6.14 | G16: 6.32 | H16: 6.07 | I16: 6.44 | J16: 5.96 | K16: 6.08
A17: Denmark | B17: 7.12 | C17: 8.15 | D17: 6.16 | E17: 8.1 | F17: 8.1 | G17: 7.53 | H17: 8.38 | I17: 7.27 | J17: 7.04 | K17: 8.6
A18: Germany | B18: 7.64 | C18: 7.64 | D18: 6.67 | E18: 7.4 | F18: 7.82 | G18: 7.3 | H18: 7.58 | I18: 7.43 | J18: 7.08 | K18: 7.29
A19: Estonia | B19: 2.77 | C19: 4.2 | D19: 2.91 | E19: 5.07 | F19: 5 | G19: 4.09 | H19: 4.72 | I19: 4 | J19: 4.3 | K19: :
A20: Ireland | B20: 8.99 | C20: 9.46 | D20: 8.37 | E20: 9.38 | F20: 7.76 | G20: 10.08 | H20: 10.43 | I20: 8.66 | J20: 8.12 | K20: 10.15
A21: Greece | B21: 3.1 | C21: 2.46 | D21: 2.65 | E21: 2.79 | F21: 3.08 | G21: 2.82 | H21: 2.92 | I21: 2.92 | J21: 3.15 | K21: 2.9
A22: Spain | B22: 3.63 | C22: 2.44 | D22: 4.03 | E22: 3.15 | F22: 4.25 | G22: 4.02 | H22: 3 | I22: 2.07 | J22: 3.83 | K22: 4.18
A23: France | B23: 5.23 | C23: 7.17 | D23: 6.76 | E23: 7.75 | F23: 6.68 | G23: 6.93 | H23: 7.01 | I23: 7.21 | J23: 5.94 | K23: 7.21
A24: Croatia | B24: 5.7 | C24: 5.87 | D24: 5.44 | E24: 5.59 | F24: 5.87 | G24: 6.7 | H24: 6 | I24: 4.83 | J24: 5.91 | K24: 5.99
A25: Italy | B25: 4.31 | C25: : | D25: : | E25: : | F25: 3.92 | G25: 4.22 | H25: 3.72 | I25: 3.69 | J25: 3.66 | K25: 4
A26: Cyprus | B26: 0.85 | C26: 1.97 | D26: 1.5 | E26: 2.78 | F26: 2.67 | G26: 2.1 | H26: 2.34 | I26: 2 | J26: 2.06 | K26: :
A27: Latvia | B27: : | C27: 4.79 | D27: 3.43 | E27: 4.81 | F27: 5.34 | G27: 4.48 | H27: 4.72 | I27: 4.07 | J27: 4.57 | K27: 4.63
A28: Lithuania | B28: 4.37 | C28: 4.82 | D28: 3.67 | E28: 4.29 | F28: 5.39 | G28: 4.5 | H28: 4.74 | I28: 4.74 | J28: 5.04 | K28: 4.8
A29: Luxembourg | B29: 5.08 | C29: 5.49 | D29: 6.19 | E29: 6.16 | F29: 6.07 | G29: 5.92 | H29: 6.33 | I29: 5.81 | J29: 5.18 | K29: :
A30: Hungary | B30: 5.37 | C30: 5.43 | D30: 5.12 | E30: 5.3 | F30: 5.47 | G30: 5.93 | H30: 4.45 | I30: 5.64 | J30: 5.79 | K30: 5.51
A31: Malta | B31: : | C31: : | D31: : | E31: : | F31: : | G31: : | H31: : | I31: : | J31: : | K31: :
A32: Netherlands | B32: 7.84 | C32: : | D32: 8.62 | E32: 9.38 | F32: 8.56 | G32: : | H32: 9.39 | I32: 8.43 | J32: 6.97 | K32: 10.08
A33: Austria | B33: 6.18 | C33: 4.82 | D33: 4.64 | E33: 5.74 | F33: 5.93 | G33: 5.53 | H33: 5.8 | I33: 6.19 | J33: 5.75 | K33: 6.2
A34: Poland | B34: 4.46 | C34: 4.79 | D34: 3.98 | E34: 4.31 | F34: 5.23 | G34: 4.98 | H34: 5.24 | I34: 5.28 | J34: : | K34: 5.2
A35: Portugal | B35: 2.44 | C35: 2.13 | D35: 2.59 | E35: 2.7 | F35: 2.77 | G35: 2.42 | H35: 1.99 | I35: 1.4 | J35: 2.51 | K35: 2.36
A36: Romania | B36: 3.94 | C36: 4.89 | D36: 4.79 | E36: 4.75 | F36: 2.97 | G36: 4.8 | H36: 4 | I36: 4.15 | J36: 4.6 | K36: 5.64
A37: Slovenia | B37: 5.19 | C37: 5.03 | D37: 4.38 | E37: 5.23 | F37: 5.8 | G37: 5.77 | H37: 5.47 | I37: 5.07 | J37: 5.47 | K37: :
A38: Slovakia | B38: : | C38: 4.74 | D38: 4.77 | E38: 4.81 | F38: 5.52 | G38: 5.61 | H38: 4.97 | I38: 6.12 | J38: 5.45 | K38: 6.04
A39: Finland | B39: 3.88 | C39: 4.18 | D39: 2.82 | E39: 4.62 | F39: 3.46 | G39: 3.23 | H39: 3.84 | I39: 3.27 | J39: 3.54 | K39: 4.3
A40: Sweden | B40: 6.33 | C40: 6.99 | D40: 4.35 | E40: 7.41 | F40: 7.16 | G40: 6.32 | H40: 7 | I40: 5.46 | J40: : | K40: 6.74
A41: Iceland | B41: : | C41: : | D41: : | E41: : | F41: : | G41: : | H41: 3.29 | I41: : | J41: : | K41: :
A42: Norway | B42: 4.6 | C42: 5.24 | D42: : | E42: : | F42: : | G42: : | H42: 5.04 | I42: 2.64 | J42: : | K42: :
...

Sheet Sheet 10
A1: Data extracted on 26/09/2025 16:39:20 from [ESTAT]
A2: Dataset: | B2: Crop production in EU standard humidity [apro_cpsh1__custom_18188015]
A3: Last updated: | B3: 17/09/2025 23:00
A5: Time frequency | C5: Annual
A6: Crops | C6: Common wheat and spelt
A7: Structure of production | C7: Area (cultivation/harvested/production) (1000 ha)
A9: TIME | B9: 2016 | C9: 2017 | D9: 2018 | E9: 2019 | F9: 2020 | G9: 2021 | H9: 2022 | I9: 2023 | J9: 2024 | K9: 2025
A10: GEO (Labels)
A11: European Union (EU6-1958, EU9-1973, EU10-1981, EU12-1986, EU15-1995, EU25-2004, EU27-2007, EU28-2013, EU27-2020) | B11: 24255.26 | C11: 23385.83 | D11: 23018.82 | E11: 23883.38 | F11: 20663.87 | G11: 21816.18 | H11: 21929.04 | I11: 21915.63 | J11: 20203.28 | K11: :
A12: European Union - 27 countries (from 2020) | B12: 22432.26 | C12: 21593.83 | D12: 21271.12 | E12: 22067.6 | F12: 20663.87 | G12: 21816.18 | H12: 21929.04 | I12: 21915.63 | J12: 20203.28 | K12: :
A13: European Union - 28 countries (2013-2020) | B13: 24255.26 | C13: 23385.83 | D13: 23018.82 | E13: 23883.38 | F13: : | G13: : | H13: : | I13: : | J13: : | K13: :
A14: Belgium | B14: 215.72 | C14: 197.59 | D14: 195.69 | E14: 203.76 | F14: 194.66 | G14: 209.18 | H14: 204.47 | I14: 212.61 | J14: 164.54 | K14: 198.13
A15: Bulgaria | B15: 1179.1 | C15: 1133.7 | D15: 1197.1 | E15: 1189.36 | F15: 1192.37 | G15: 1197.23 | H15: 1194.52 | I15: 1205.4 | J15: 1169.88 | K15: 1233
A16: Czechia | B16: 839.71 | C16: 832.06 | D16: 819.69 | E16: 839.45 | F16: 798.58 | G16: 784.78 | H16: 854.43 | I16: 814.29 | J16: 771.61 | K16: 777.12
A17: Denmark | B17: 583 | C17: 586.6 | D17: 425.8 | E17: 573.4 | F17: 502.6 | G17: 537.7 | H17: 497.3 | I17: 489 | J17: 475.6 | K17: 473.78
A18: Germany | B18: 3176.4 | C18: 3173 | D18: 3006.2 | E18: 3086.7 | F18: 2801.5 | G18: 2901.5 | H18: 2940.1 | I18: 2856.4 | J18: 2566.7 | K18: 2906.6
A19: Estonia | B19: 164.5 | C19: 169.75 | D19: 154.58 | E19: 166.98 | F19: 168.04 | G19: 180 | H19: 180.97 | I19: 173.57 | J19: 173.32 | K19: :
A20: Ireland | B20: 67.92 | C20: 67.05 | D20: 57.98 | E20: 63.48 | F20: 46.99 | G20: 62.33 | H20: 67.23 | I20: 55.78 | J20: 47.8 | K20: 64.09
A21: Greece | B21: 149.42 | C21: 119.7 | D21: 108 | E21: 96.61 | F21: 93.2 | G21: 97.11 | H21: 94.79 | I21: 115.96 | J21: 89.32 | K21: 114.1
A22: Spain | B22: 1808.69 | C22: 1645.12 | D22: 1689.08 | E22: 1653.45 | F22: 1663.76 | G22: 1869.42 | H22: 1894.04 | I22: 1685.72 | J22: 1702.91 | K22: 1793.57
A23: France | B23: 5139.25 | C23: 4962.08 | D23: 4880.21 | E23: 4998.75 | F23: 4267.5 | G23: 4982.51 | H23: 4696.9 | I23: 4761.95 | J23: 4217.51 | K23: 4484.44
A24: Croatia | B24: 170.9 | C24: 117.73 | D24: 137.99 | E24: 142.76 | F24: 147.08 | G24: 146.7 | H24: 161 | I24: 172.52 | J24: 136.8 | K24: 150.6
A25: Italy | B25: 528.74 | C25: 501.72 | D25: 543.32 | E25: 530.68 | F25: 500.8 | G25: 498.11 | H25: 538.77 | I25: 598.28 | J25: 520.31 | K25: 497.68
A26: Cyprus | B26: 0.78 | C26: 1.57 | D26: 2.43 | E26: 4.2 | F26: 5.36 | G26: 4.9 | H26: 5.03 | I26: 5.42 | J26: 5 | K26: :
A27: Latvia | B27: 479.1 | C27: 446.8 | D27: 417.2 | E27: 492.7 | F27: 498.2 | G27: 537.3 | H27: 537.5 | I27: 525 | J27: 540 | K27: 545.6
A28: Lithuania | B28: 880.53 | C28: 811.95 | D28: 772.89 | E28: 895.76 | F28: 893.51 | G28: 944.17 | H28: 946.72 | I28: 940.29 | J28: 836.67 | K28: 829.69
A29: Luxembourg | B29: 13.81 | C29: 14.11 | D29: 12.87 | E29: 13.36 | F29: 11.8 | G29: 12.58 | H29: 13.3 | I29: 12.3 | J29: 12.54 | K29: :
A30: Hungary | B30: 1014.53 | C30: 932.82 | D30: 981.88 | E30: 978.72 | F30: 909.61 | G30: 863.3 | H30: 942.3 | I30: 1015.84 | J30: 871.15 | K30: 986.83
A31: Malta | B31: 0 | C31: 0 | D31: 0 | E31: 0 | F31: 0 | G31: 0 | H31: 0 | I31: 0 | J31: 0 | K31: :
A32: Netherlands | B32: 127.33 | C32: 115.92 | D32: 111.66 | E32: 120.55 | F32: 108.91 | G32: 118.14 | H32: 123.8 | I32: 129.55 | J32: 95.85 | K32: 112.71
A33: Austria | B33: 294.51 | C33: 274.39 | D33: 272.39 | E33: 261.64 | F33: 262.51 | G33: 260.4 | H33: 272.24 | I33: 258.57 | J33: 247.96 | K33: 255.97
A34: Poland | B34: 2364.1 | C34: 2391.85 | D34: 2417.23 | E34: 2511.33 | F34: 2391 | G34: 2390.52 | H34: 2518.44 | I34: 2449.33 | J34: 2385.69 | K34: 2423.12
A35: Portugal | B35: 33.51 | C35: 24.89 | D35: 22.87 | E35: 24.32 | F35: 26.52 | G35: 24.32 | H35: 25.57 | I35: 21.22 | J35: 22.28 | K35: 21.32
A36: Romania | B36: 2130.71 | C36: 2048.13 | D36: 2110.52 | E36: 2162.64 | F36: 2150.99 | G36: 2167.72 | H36: 2162.1 | I36: 2311.1 | J36: 2195.93 | K36: 2294.09
A37: Slovenia | B37: 31.46 | C37: 28.02 | D37: 27.82 | E37: 26.73 | F37: 27.29 | G37: 26.76 | H37: : | I37: : | J37: : | K37: :
A38: Slovakia | B38: 374.31 | C38: 331.12 | D38: 355.42 | E38: 363.21 | F38: 353.14 | G38: 307.99 | H38: 348.79 | I38: 340.1 | J38: 236.27 | K38: 292.5
A39: Finland | B39: 215.1 | C39: 194.3 | D39: 177.8 | E39: 197.6 | F39: 198.8 | G39: 212.41 | H39: 219.64 | I39: 229.2 | J39: 214.75 | K39: 227.17
A40: Sweden | B40: 449.15 | C40: 471.87 | D40: 372.5 | E40: 469.49 | F40: 449.17 | G40: 479.13 | H40: 461.57 | I40: 507.54 | J40: 474.94 | K40: 527.6
A41: Iceland | B41: 0 | C41: 0 | D41: 0 | E41: 0 | F41: 0 | G41: 0.1 | H41: 0.06 | I41: 0.05 | J41: 0.05 | K41: :
A42: Norway | B42: 66.77 | C42: 75.75 | D42: 58.65 | E42: 80.35 | F42: 67.67 | G42: 63.59 | H42: 75.3 | I42: 64.46 | J42: : | K42: :
...

Sheet Sheet 11
A1: Data extracted on 26/09/2025 16:39:20 from [ESTAT]
A2: Dataset: | B2: Crop production in EU standard humidity [apro_cpsh1__custom_18188015]
A3: Last updated: | B3: 17/09/2025 23:00
A5: Time frequency | C5: Annual
A6: Crops | C6: Common wheat and spelt
A7: Structure of production | C7: Harvested production in EU standard humidity (1000 t)
A9: TIME | B9: 2016 | C9: 2017 | D9: 2018 | E9: 2019 | F9: 2020 | G9: 2021 | H9: 2022 | I9: 2023 | J9: 2024 | K9: 2025
A10: GEO (Labels)
A11: European Union (EU6-1958, EU9-1973, EU10-1981, EU12-1986, EU15-1995, EU25-2004, EU27-2007, EU28-2013, EU27-2020) | B11: 134713 | C11: 142599.48 | D11: 128988.96 | E11: 147871.89 | F11: 118867.61 | G11: 129884.27 | H11: 126640.47 | I11: 125878.52 | J11: 112535.45 | K11: :
A12: European Union - 27 countries (from 2020) | B12: 120497.24 | C12: 127935 | D12: 115591.58 | E12: 131836.03 | F12: 118867.61 | G12: 129884.27 | H12: 126640.47 | I12: 125878.52 | J12: 112535.45 | K12: :
A13: European Union - 28 countries (2013-2020) | B13: 134713 | C13: 142599.48 | D13: 128988.96 | E13: 147871.89 | F13: : | G13: : | H13: : | I13: : | J13: : | K13: :
A14: Belgium | B14: 1431.44 | C14: 1690.84 | D14: 1661.86 | E14: 1902.38 | F14: 1741.48 | G14: 1629.18 | H14: 1851.87 | I14: 1791.17 | J14: 1085.38 | K14: 1421.58
A15: Bulgaria | B15: 5745.29 | C15: 6271.58 | D15: 5893.53 | E15: 6280.15 | F15: 4817.68 | G15: 7292.73 | H15: 6389.69 | I15: 6776.54 | J15: 6978.03 | K15: 7418.05
A16: Czechia | B16: 5454.66 | C16: 4718.21 | D16: 4417.84 | E16: 4812.16 | F16: 4902.41 | G16: 4960.93 | H16: 5188.69 | I16: 5243.15 | J16: 4598.29 | K16: 4730.99
A17: Denmark | B17: 4152.65 | C17: 4777.89 | D17: 2623.93 | E17: 4642.09 | F17: 4070.41 | G17: 4047.09 | H17: 4165.4 | I17: 3556.26 | J17: 3348.01 | K17: 4073.47
A18: Germany | B18: 24329.2 | C18: 24311.2 | D18: 20125.4 | E18: 22907.9 | F18: 21989 | G18: 21252.2 | H18: 22368.9 | I18: 21297.9 | J18: 18241.2 | K18: 21265.5
A19: Estonia | B19: 455.5 | C19: 713.26 | D19: 450.27 | E19: 846.58 | F19: 840.52 | G19: 736.27 | H19: 854.12 | I19: 694.12 | J19: 744.75 | K19: :
A20: Ireland | B20: 610.24 | C20: 634.4 | D20: 485.48 | E20: 595.36 | F20: 364.92 | G20: 628.08 | H20: 701.24 | I20: 483.11 | J20: 388.1 | K20: 650.45
A21: Greece | B21: 492.52 | C21: 302.85 | D21: 298.63 | E21: 295.28 | F21: 301.42 | G21: 278.24 | H21: 262.75 | I21: 345.92 | J21: 265.83 | K21: 335.67
A22: Spain | B22: 7092.59 | C22: 3922.01 | D22: 6980.39 | E22: 5304.31 | F22: 7319.46 | G22: 7758.38 | H22: 5813.5 | I22: 3610.75 | J22: 6708.82 | K22: 7736.65
A23: France | B23: 27299.47 | C23: 36134.03 | D23: 33649.54 | E23: 39056.97 | F23: 28870.79 | G23: 34984.89 | H23: 33302.04 | I23: 34709.32 | J23: 25341.44 | K23: 32688.11
A24: Croatia | B24: 966.55 | C24: 692.26 | D24: 751.13 | E24: 801.47 | F24: 864.28 | G24: 983.39 | H24: 967.22 | I24: 833.16 | J24: 809.2 | K24: 903.38
A25: Italy | B25: 3052.49 | C25: 2812.61 | D25: 2848.06 | E25: 2785.8 | F25: 2725.74 | G25: 3118.59 | H25: 2818.79 | I25: 3104.83 | J25: 2617.8 | K25: 2640.1
A26: Cyprus | B26: 0.32 | C26: 2.83 | D26: 2.89 | E26: 11.01 | F26: 14.24 | G26: 9.66 | H26: 11.41 | I26: 10.12 | J26: 9.29 | K26: :
A27: Latvia | B27: 2062.3 | C27: 2138.8 | D27: 1431.6 | E27: 2371 | F27: 2659.6 | G27: 2407.7 | H27: 2539.4 | I27: 2136.8 | J27: 2465.9 | K27: 2525.7
A28: Lithuania | B28: 3844.49 | C28: 3917.37 | D28: 2838.9 | E28: 3843.85 | F28: 4818.75 | G28: 4248.85 | H28: 4482.76 | I28: 4455.39 | J28: 4218.3 | K28: 3984.95
A29: Luxembourg | B29: 70.15 | C29: 77.55 | D29: 79.65 | E29: 82.26 | F29: 71.87 | G29: 74.76 | H29: 84.55 | I29: 71.71 | J29: 65.22 | K29: :
A30: Hungary | B30: 5453.3 | C30: 5087.15 | D30: 5049.34 | E30: 5215.24 | F30: 5000.79 | G30: 5127.89 | H30: 4218.47 | I30: 5744.88 | J30: 5067.95 | K30: 5450.44
A31: Malta | B31: 0 | C31: 0 | D31: 0 | E31: 0 | F31: 0 | G31: 0 | H31: 0 | I31: 0 | J31: 0 | K31: :
A32: Netherlands | B32: 995.2 | C32: 1032.21 | D32: 961.92 | E32: 1130.53 | F32: 931.83 | G32: 947.25 | H32: 1162.81 | I32: 1096.82 | J32: 668.17 | K32: 1136.65
A33: Austria | B33: 1842.28 | C33: 1343.3 | D33: 1276.2 | E33: 1516.63 | F33: 1573.87 | G33: 1459.35 | H33: 1592.7 | I33: 1605.62 | J33: 1435.79 | K33: 1602.1
A34: Poland | B34: 10626.45 | C34: 11448.66 | D34: 9637.62 | E34: 10807.49 | F34: 12515.06 | G34: 11893.55 | H34: 13195.12 | I34: 12932.39 | J34: 12183.62 | K34: 12591.69
A35: Portugal | B35: 80 | C35: 52.02 | D35: 58.54 | E35: 64.87 | F35: 72.87 | G35: 57.17 | H35: 48.82 | I35: 28.57 | J35: 54.23 | K35: 51.19
A36: Romania | B36: 8406.48 | C36: 10014.38 | D36: 10122.91 | E36: 10280.58 | F36: 6381.69 | G36: 10404.08 | H36: 8661.22 | I36: 9602.34 | J36: 10112.41 | K36: 12965.11
A37: Slovenia | B37: 163.17 | C37: 140.96 | D37: 121.9 | E37: 139.81 | F37: 158.18 | G37: 154.29 | H37: : | I37: : | J37: : | K37: :
A38: Slovakia | B38: 2194.48 | C38: 1587.77 | D38: 1702.16 | E38: 1751.33 | F38: 1959.82 | G38: 1714.81 | H38: 1735.46 | I38: 2085.08 | J38: 1289.35 | K38: 1766
A39: Finland | B39: 834.44 | C39: 812.26 | D39: 501.6 | E39: 914.18 | F39: 686.62 | G39: 687.16 | H39: 844.24 | I39: 749.01 | J39: 759.38 | K39: 977.76
A40: Sweden | B40: 2841.6 | C40: 3298.6 | D40: 1620.3 | E40: 3476.8 | F40: 3214.3 | G40: 3027.8 | H40: 3228.7 | I40: 2768.2 | J40: 2926 | K40: 3558.2
A41: Iceland | B41: 0 | C41: 0 | D41: 0 | E41: 0 | F41: 0 | G41: 0 | H41: 0.2 | I41: 0.1 | J41: 0.1 | K41: :
A42: Norway | B42: 305.79 | C42: 395.83 | D42: 136.07 | E42: 444.83 | F42: 324 | G42: 261.8 | H42: 379.53 | I42: 170 | J42: : | K42: :
...

Sheet Sheet 12
A1: Data extracted on 26/09/2025 16:39:20 from [ESTAT]
A2: Dataset: | B2: Crop production in EU standard humidity [apro_cpsh1__custom_18188015]
A3: Last updated: | B3: 17/09/2025 23:00
A5: Time frequency | C5: Annual
A6: Crops | C6: Common wheat and spelt
A7: Structure of production | C7: Yield in EU standard humidity (tonne/ha)
A9: TIME | B9: 2016 | C9: 2017 | D9: 2018 | E9: 2019 | F9: 2020 | G9: 2021 | H9: 2022 | I9: 2023 | J9: 2024 | K9: 2025
A10: GEO (Labels)
